Workbook
Name PortfolioName: Vorgaben!$C$7
Name Jahr: Vorgaben!$C$8
Name StichtagEingabe: Vorgaben!$C$9
Name Stichtag: Vorgaben!$C$10
Name SteuersatzBasis: Vorgaben!$C$15
Name Kirchensteuer: Vorgaben!$C$16
Name Soli: Vorgaben!$C$17
Name SteuersatzEff: Vorgaben!$C$18
Name Szenario: Vorgaben!$C$22
Name Mietsteigerung: Vorgaben!$C$37
Name Wertsteigerung: Vorgaben!$C$38
Name Inflation: Vorgaben!$C$39
Name Leerstand: Vorgaben!$C$40
Name InstandProzent: Vorgaben!$C$41
Name Anschlusszins: Vorgaben!$C$42
Name PrognoseJahre: Vorgaben!$C$33
Name VerkaufNach: Vorgaben!$C$46
Name Verkaufskosten: Vorgaben!$C$47
Name VorgabeGrESt: Vorgaben!$C$51
Name VorgabeNotar: Vorgaben!$C$52
Name VorgabeMakler: Vorgaben!$C$53
Name Objekttypen: Kern!$B$4:$B$8
Name Darlehensarten: Kern!$C$4:$C$6
Name JaNein: Kern!$D$4:$D$5
Name Anpassungsarten: Kern!$E$4:$E$6
Name Kirchensaetze: Kern!$F$4:$F$6
Name Szenarien: Kern!$H$4:$H$6
Name SzenMiete: Kern!$I$4:$I$6
Name SzenWert: Kern!$J$4:$J$6
Name SzenLeer: Kern!$K$4:$K$6
Name SzenAnschluss: Kern!$L$4:$L$6
Name SzenInstand: Kern!$M$4:$M$6
Name Bundeslaender: Kern!$O$4:$O$19
Name GrEStSatz: Kern!$P$4:$P$19
Name Zahlungsarten: Kern!$R$4:$R$13
Name Monatsnamen: Kern!$V$4:$V$15
Name ObjNr: Objekte!$B$8:$B$17
Name ObjBezeichnung: Objekte!$C$8:$C$17
Name ObjTyp: Objekte!$D$8:$D$17
Name ObjKaufdatum: Objekte!$H$8:$H$17
Name ObjKaufpreis: Objekte!$I$8:$I$17
Name ObjHausgeld: Objekte!$R$8:$R$17
Name ObjUmlage: Objekte!$S$8:$S$17
Name ObjVerwaltung: Objekte!$T$8:$T$17
Name ObjInstand: Objekte!$U$8:$U$17
Name ObjSonstige: Objekte!$V$8:$V$17
Name ObjWert: Objekte!$W$8:$W$17
Name ObjInvest: Objekte!$AA$8:$AA$17
Name ObjNkSumme: Objekte!$Z$8:$Z$17
Name ObjAfaJahr: Objekte!$AD$8:$AD$17
Name ObjAfaDauer: Objekte!$AE$8:$AE$17
Name ObjBewirt: Objekte!$AF$8:$AF$17
Name ObjSteuersatz: Objekte!$AG$8:$AG$17
Name ObjFlaeche: Objekte!$AH$8:$AH$17
Name ObjKaufJahr: Objekte!$AI$8:$AI$17
Name ObjKaufMonat: Objekte!$AJ$8:$AJ$17
Name ObjBelegt: Objekte!$AK$8:$AK$17
Name ObjLaufend: Objekte!$AL$8:$AL$17
Name ObjInstandBasis: Objekte!$AM$8:$AM$17
Name ObjWertEff: Objekte!$AN$8:$AN$17

Sheet Übersicht
C2: ZAHLENKOMPASS
C3: ImmoPortfolio
C4: ="Immobilien-Portfolio "&Jahr&" · Tabellenfassung für Excel und Google Sheets"
C6: So richtest du die Mappe ein
B7: 1 | C7: Vorgaben ausfüllen | E7: Name, Jahr, Steuersatz und die Annahmen für die Prognose. Der Stichtag darf leer bleiben – dann rechnet die Mappe mit dem heutigen Tag.
B8: 2 | C8: Objekte eintragen | E8: Blatt Objekte, Block A. Kaufpreis, Kaufdatum und Fläche genügen für den Anfang. Die Grunderwerbsteuer kommt aus dem Bundesland, wenn du keinen eigenen Prozentsatz einträgst.
B9: 3 | C9: Einheiten anlegen | E9: Blatt Objekte, Block B. Auch ein Objekt mit nur einer Wohnung braucht eine Zeile – die Mietverträge hängen daran.
B10: 4 | C10: Mietverträge erfassen | E10: Bis zu drei Konditionen je Vertrag. Eine Staffel ist einfach eine weitere Kondition mit späterem "gilt ab".
B11: 5 | C11: Darlehen erfassen | E11: Betrag, Auszahlung, Sollzins und Anfangstilgung reichen. Sondertilgungen stehen im Block darunter.
B12: 6 | C12: Ablesen | E12: Dashboard für das Ganze, Objekte im Detail für einzelne Immobilien, Prognose für die Zukunft.
C14: Die Blätter
B15: · | C15: Vorgaben | E15: Alles, was für die ganze Mappe gilt: Steuern, Annahmen, Szenario, Verkauf.
B16: · | C16: Objekte | E16: A Stammdaten · B Einheiten · C Kennzahlen je Objekt im Vergleich.
B17: · | C17: Mietverträge | E17: A Verträge mit Staffeln · B Miete je Objekt.
B18: · | C18: Darlehen | E18: A Darlehen · B Sondertilgungen · C Kennzahlen je Darlehen.
B19: · | C19: Tilgungsplan | E19: Ein Darlehen zur Auswahl, Monat für Monat.
B20: · | C20: Zahlungen | E20: A Summen je Gruppe · B tatsächliche Zahlungen · C Korrekturen.
B21: · | C21: Objekte im Detail | E21: Je Objekt ein Block von 26 Zeilen. Objekt 1 beginnt in Zeile 6.
B22: · | C22: Prognose | E22: Jahr für Jahr über das Portfolio, dazu die Verkaufsrechnung.
B23: · | C23: Dashboard | E23: Bestand, Finanzierung, Rendite, Cashflow und Hinweise auf einen Blick.
C25: So liest du die Farben
C26: Weiß mit blauem Rand | E26: Eingabe – nur hier wird getippt.
C27: Grau | E27: Gerechnet. Eine Änderung hier zerstört die Formel.
C28: Gelb | E28: Ein Wert wurde von Hand korrigiert.
C29: Rot | E29: Beanstandung: negativer Cashflow, Leerstand, Kapitaldienstdeckung unter eins, überschrittenes Sondertilgungsrecht, unpassender Stichtag. Steht nichts in Rot, gibt es nichts zu tun.
C31: Die Mappe ist bewusst nicht geschützt. | E31: Google Sheets übernimmt einen Blattschutz beim Import nur halb; eine Sperre, die mal greift und mal nicht, verwirrt mehr, als sie nützt. Die Farbe genügt.
C33: So wird gerechnet
B34: · | C34: Cashflow | E34: Kaltmiete − nicht umlagefähige Bewirtschaftung − Zinsen − Tilgung = Cashflow vor Steuern. Die Tilgung mindert den Cashflow, aber nicht die Steuer; die AfA mindert die Steuer, aber nicht den Cashflow.
B35: · | C35: Steuer | E35: Kaltmiete − Bewirtschaftung − Zinsen − AfA = Einkünfte aus Vermietung, mal effektivem Steuersatz. Soli und Kirchensteuer kommen auf die Einkommensteuer, nicht auf das Einkommen.
B36: · | C36: Abschreibung | E36: Der Grundstücksanteil wird auf den reinen Kaufpreis angewendet – die Kaufnebenkosten zählen damit vollständig zum Gebäude. Im Kaufjahr wird ab dem Kaufmonat zeitanteilig abgeschrieben.
B37: · | C37: Tilgung | E37: Nachschüssige Annuität, monatlich verrechnet. Die erste Rate fällt im Monat nach der Auszahlung an. Nach Ablauf der Zinsbindung läuft die bisherige Rate weiter, solange sie mindestens 1 % der Restschuld tilgt.
B38: · | C38: Renditen | E38: Rechnen immer mit zwölf mal der aktuellen Monatsmiete, damit ein angeschnittenes Anschaffungsjahr sie nicht verzerrt.
B39: · | C39: Nebenkosten | E39: Umlagefähige Kosten und Nebenkosten-Vorauszahlungen sind ein durchlaufender Posten und bleiben im Cashflow außen vor.
C41: Grenzen dieser Mappe
B42: · | C42: Ein Szenario zur Zeit | E42: Der Umschalter auf dem Blatt Vorgaben ändert die ganze Mappe – auch die Tilgungspläne, weil der Anschlusszins vom Szenario abhängt. Die drei Szenarien vergleichst du durch Umschalten.
B43: · | C43: Ein Kalenderjahr | E43: Zahlungen, Korrekturen und der Cashflow-Block gelten für das Jahr auf dem Blatt Vorgaben. Ein anderes Jahr ist eine neu erzeugte Mappe.
B44: · | C44: Zahlungen je Objekt und Art | E44: Mehrere Mietverträge oder Darlehen eines Objekts erscheinen summiert, nicht einzeln.
B45: · | C45: Platz | E45: 10 Objekte, 30 Einheiten, 30 Mietverträge mit je 3 Konditionen, 20 Darlehen, 40 Sondertilgungen.
B46: · | C46: Zeitraum | E46: Die Prognose reicht 30 Jahre. Ein Tilgungsplan wird über 40 Jahre ab seiner Auszahlung gerechnet – für ein Darlehen, das lange vor dem Jahr der Mappe ausgezahlt wurde, kann das am Ende der Prognose knapp werden. Das Dashboard sagt es, wenn es so ist.
B47: · | C47: Ein Verkehrswert je Objekt | E47: Keine Werthistorie, ein Feld für aktivierte Modernisierungen statt einer Liste.
...

Sheet Vorgaben
B2: ZAHLENKOMPASS
B3: Vorgaben
B4: ="ImmoPortfolio · Tabellenfassung "&Jahr&" · alles, was für die ganze Mappe gilt"
B6: Portfolio
B7: Name | E7: Erscheint auf der Übersicht und im Dashboard.
B8: Jahr der Mappe | C8: 2026 | E8: Zahlungen und Cashflow gelten für dieses Jahr, die Prognose startet hier.
B9: Stichtag | E9: Leer lassen = heute. Maßgeblich für Restschuld, laufende Miete und alle Renditen.
B10: wirksamer Stichtag | C10: =IF(StichtagEingabe="",TODAY(),StichtagEingabe)
C11: =IF(YEAR(Stichtag)=Jahr,"","Achtung") | E11: =IF(YEAR(Stichtag)=Jahr,"","Der Stichtag liegt nicht im Jahr der Mappe. Jahreswerte und Stichtagswerte passen dann nicht zusammen.")
B14: Steuern
B15: Persönlicher Grenzsteuersatz | C15: 42
B16: Kirchensteuer | C16: 0 | E16: 0, 8 oder 9 Prozent – auf die Einkommensteuer, nicht auf das Einkommen.
B17: Solidaritätszuschlag | C17: Nein | E17: 5,5 Prozent auf die Einkommensteuer.
B18: effektiver Steuersatz | C18: =SteuersatzBasis*(1+(IF(Soli="Ja",5.5,0)+Kirchensteuer)/100) | E18: Gilt für alle Objekte ohne eigenen Satz.
B21: Szenario
B22: Gewähltes Szenario | C22: Basis | E22: Die ganze Mappe rechnet mit diesem Szenario – auch die Tilgungspläne.
E23: Zum Vergleich der drei Szenarien schaltest du hier um und liest das Dashboard erneut.
B26: Annahmen (Basis)
B27: Mietsteigerung p. a. | C27: 1.5 | E27: Negative Werte senken die Miete.
B28: Wertsteigerung p. a. | C28: 2
B29: Inflation p. a. | C29: 2 | E29: Schreibt die Bewirtschaftungskosten fort.
B30: Leerstandsquote | C30: 2 | E30: Nur in der Prognose, nicht in den Ist-Zahlungen.
B31: Instandhaltung vom Kaufpreis p. a. | C31: 1 | E31: Greift nur, wenn am Objekt kein eigener Betrag steht.
B32: Anschlusszins | C32: 4.5 | E32: Nach Ablauf der Zinsbindung, sofern am Darlehen nichts anderes steht.
B33: Prognosejahre | C33: 20 | E33: Höchstens 30. Die Tabelle rechnet immer bis 30, zeigt aber nur so viele Jahre.
B36: Im gewählten Szenario wirksam
B37: Mietsteigerung p. a. | C37: =$C$27+INDEX(SzenMiete,MATCH(Szenario,Szenarien,0))
B38: Wertsteigerung p. a. | C38: =$C$28+INDEX(SzenWert,MATCH(Szenario,Szenarien,0))
B39: Inflation p. a. | C39: =$C$29
B40: Leerstandsquote | C40: =MAX(0,$C$30+INDEX(SzenLeer,MATCH(Szenario,Szenarien,0)))
B41: Instandhaltung p. a. | C41: =MAX(0,$C$31+INDEX(SzenInstand,MATCH(Szenario,Szenarien,0)))
B42: Anschlusszins | C42: =MAX(0,$C$32+INDEX(SzenAnschluss,MATCH(Szenario,Szenarien,0)))
B45: Verkauf (freiwillig)
B46: Verkauf nach Jahren | E46: Leer lassen = kein Verkauf. Innerhalb von zehn Jahren wird der Gewinn versteuert.
B47: Verkaufskosten | C47: 3 | E47: Vom Verkaufserlös.
B50: Kaufnebenkosten – Vorbelegung
B51: Grunderwerbsteuer | C51: 6.5 | E51: Gilt, wenn am Objekt weder Prozentsatz noch Bundesland steht.
B52: Notar und Grundbuch | C52: 1.5
B53: Maklerprovision | C53: 3.57

Sheet Objekte
B2: ZAHLENKOMPASS
B3: Objekte
B4: ="Stammdaten, Einheiten und Kennzahlen · "&Jahr
B6: A · Stammdaten | H6: weiß mit blauem Rand = hier wird getippt
B7: Nr | C7: Bezeichnung | D7: Typ | E7: Ort | F7: Baujahr | G7: Fläche m² | H7: Kaufdatum | I7: Kaufpreis | J7: Bundesland | K7: GrESt % | L7: Notar % | M7: Makler % | N7: Weitere NK € | O7: Grundstück % | P7: AfA % | Q7: Modernis. € | R7: Hausgeld/M | S7: davon umlagef./M | T7: Verwaltung/M | U7: Instandh./M | V7: Sonstige/Jahr | W7: Verkehrswert | X7: Steuersatz %
B8: 1 | O8: 20 | P8: 2 | Z8: =$I8*($AO8+IF($L8="",VorgabeNotar,$L8)+IF($M8="",VorgabeMakler,$M8))/100+$N8 | AA8: =$I8+$Z8 | AB8: =$I8*$O8/100 | AC8: =MAX(0,$AA8-$AB8)+$Q8 | AD8: =$AC8*$P8/100 | AE8: =IF($P8=0,0,100/$P8) | AF8: =(MAX(0,$R8-$S8)+$T8+$U8)*12+$V8 | AG8: =IF($X8="",SteuersatzEff,$X8*(1+(IF(Soli="Ja",5.5,0)+Kirchensteuer)/100)) | AH8: =IF(SUMIF(EhObj,$B8,EhFlaeche)>0,SUMIF(EhObj,$B8,EhFlaeche),$G8) | AI8: =IF($H8="",0,YEAR($H8)) | AJ8: =IF($H8="",1,MONTH($H8)) | AK8: =IF($C8="",0,1) | AL8: =(MAX(0,$R8-$S8)+$T8)*12+$V8 | AM8: =IF($U8>0,$U8*12,$I8*InstandProzent/100) | AN8: =IF($W8="",$I8,$W8) | AO8: =IF($K8<>"",$K8,IF($J8="",VorgabeGrESt,IFERROR(INDEX(GrEStSatz,MATCH($J8,Bundeslaender,0)),VorgabeGrESt)))
B9: 2 | O9: 20 | P9: 2 | Z9: =$I9*($AO9+IF($L9="",VorgabeNotar,$L9)+IF($M9="",VorgabeMakler,$M9))/100+$N9 | AA9: =$I9+$Z9 | AB9: =$I9*$O9/100 | AC9: =MAX(0,$AA9-$AB9)+$Q9 | AD9: =$AC9*$P9/100 | AE9: =IF($P9=0,0,100/$P9) | AF9: =(MAX(0,$R9-$S9)+$T9+$U9)*12+$V9 | AG9: =IF($X9="",SteuersatzEff,$X9*(1+(IF(Soli="Ja",5.5,0)+Kirchensteuer)/100)) | AH9: =IF(SUMIF(EhObj,$B9,EhFlaeche)>0,SUMIF(EhObj,$B9,EhFlaeche),$G9) | AI9: =IF($H9="",0,YEAR($H9)) | AJ9: =IF($H9="",1,MONTH($H9)) | AK9: =IF($C9="",0,1) | AL9: =(MAX(0,$R9-$S9)+$T9)*12+$V9 | AM9: =IF($U9>0,$U9*12,$I9*InstandProzent/100) | AN9: =IF($W9="",$I9,$W9) | AO9: =IF($K9<>"",$K9,IF($J9="",VorgabeGrESt,IFERROR(INDEX(GrEStSatz,MATCH($J9,Bundeslaender,0)),VorgabeGrESt)))
B10: 3 | O10: 20 | P10: 2 | Z10: =$I10*($AO10+IF($L10="",VorgabeNotar,$L10)+IF($M10="",VorgabeMakler,$M10))/100+$N10 | AA10: =$I10+$Z10 | AB10: =$I10*$O10/100 | AC10: =MAX(0,$AA10-$AB10)+$Q10 | AD10: =$AC10*$P10/100 | AE10: =IF($P10=0,0,100/$P10) | AF10: =(MAX(0,$R10-$S10)+$T10+$U10)*12+$V10 | AG10: =IF($X10="",SteuersatzEff,$X10*(1+(IF(Soli="Ja",5.5,0)+Kirchensteuer)/100)) | AH10: =IF(SUMIF(EhObj,$B10,EhFlaeche)>0,SUMIF(EhObj,$B10,EhFlaeche),$G10) | AI10: =IF($H10="",0,YEAR($H10)) | AJ10: =IF($H10="",1,MONTH($H10)) | AK10: =IF($C10="",0,1) | AL10: =(MAX(0,$R10-$S10)+$T10)*12+$V10 | AM10: =IF($U10>0,$U10*12,$I10*InstandProzent/100) | AN10: =IF($W10="",$I10,$W10) | AO10: =IF($K10<>"",$K10,IF($J10="",VorgabeGrESt,IFERROR(INDEX(GrEStSatz,MATCH($J10,Bundeslaender,0)),VorgabeGrESt)))
B11: 4 | O11: 20 | P11: 2 | Z11: =$I11*($AO11+IF($L11="",VorgabeNotar,$L11)+IF($M11="",VorgabeMakler,$M11))/100+$N11 | AA11: =$I11+$Z11 | AB11: =$I11*$O11/100 | AC11: =MAX(0,$AA11-$AB11)+$Q11 | AD11: =$AC11*$P11/100 | AE11: =IF($P11=0,0,100/$P11) | AF11: =(MAX(0,$R11-$S11)+$T11+$U11)*12+$V11 | AG11: =IF($X11="",SteuersatzEff,$X11*(1+(IF(Soli="Ja",5.5,0)+Kirchensteuer)/100)) | AH11: =IF(SUMIF(EhObj,$B11,EhFlaeche)>0,SUMIF(EhObj,$B11,EhFlaeche),$G11) | AI11: =IF($H11="",0,YEAR($H11)) | AJ11: =IF($H11="",1,MONTH($H11)) | AK11: =IF($C11="",0,1) | AL11: =(MAX(0,$R11-$S11)+$T11)*12+$V11 | AM11: =IF($U11>0,$U11*12,$I11*InstandProzent/100) | AN11: =IF($W11="",$I11,$W11) | AO11: =IF($K11<>"",$K11,IF($J11="",VorgabeGrESt,IFERROR(INDEX(GrEStSatz,MATCH($J11,Bundeslaender,0)),VorgabeGrESt)))
B12: 5 | O12: 20 | P12: 2 | Z12: =$I12*($AO12+IF($L12="",VorgabeNotar,$L12)+IF($M12="",VorgabeMakler,$M12))/100+$N12 | AA12: =$I12+$Z12 | AB12: =$I12*$O12/100 | AC12: =MAX(0,$AA12-$AB12)+$Q12 | AD12: =$AC12*$P12/100 | AE12: =IF($P12=0,0,100/$P12) | AF12: =(MAX(0,$R12-$S12)+$T12+$U12)*12+$V12 | AG12: =IF($X12="",SteuersatzEff,$X12*(1+(IF(Soli="Ja",5.5,0)+Kirchensteuer)/100)) | AH12: =IF(SUMIF(EhObj,$B12,EhFlaeche)>0,SUMIF(EhObj,$B12,EhFlaeche),$G12) | AI12: =IF($H12="",0,YEAR($H12)) | AJ12: =IF($H12="",1,MONTH($H12)) | AK12: =IF($C12="",0,1) | AL12: =(MAX(0,$R12-$S12)+$T12)*12+$V12 | AM12: =IF($U12>0,$U12*12,$I12*InstandProzent/100) | AN12: =IF($W12="",$I12,$W12) | AO12: =IF($K12<>"",$K12,IF($J12="",VorgabeGrESt,IFERROR(INDEX(GrEStSatz,MATCH($J12,Bundeslaender,0)),VorgabeGrESt)))
B13: 6 | O13: 20 | P13: 2 | Z13: =$I13*($AO13+IF($L13="",VorgabeNotar,$L13)+IF($M13="",VorgabeMakler,$M13))/100+$N13 | AA13: =$I13+$Z13 | AB13: =$I13*$O13/100 | AC13: =MAX(0,$AA13-$AB13)+$Q13 | AD13: =$AC13*$P13/100 | AE13: =IF($P13=0,0,100/$P13) | AF13: =(MAX(0,$R13-$S13)+$T13+$U13)*12+$V13 | AG13: =IF($X13="",SteuersatzEff,$X13*(1+(IF(Soli="Ja",5.5,0)+Kirchensteuer)/100)) | AH13: =IF(SUMIF(EhObj,$B13,EhFlaeche)>0,SUMIF(EhObj,$B13,EhFlaeche),$G13) | AI13: =IF($H13="",0,YEAR($H13)) | AJ13: =IF($H13="",1,MONTH($H13)) | AK13: =IF($C13="",0,1) | AL13: =(MAX(0,$R13-$S13)+$T13)*12+$V13 | AM13: =IF($U13>0,$U13*12,$I13*InstandProzent/100) | AN13: =IF($W13="",$I13,$W13) | AO13: =IF($K13<>"",$K13,IF($J13="",VorgabeGrESt,IFERROR(INDEX(GrEStSatz,MATCH($J13,Bundeslaender,0)),VorgabeGrESt)))
B14: 7 | O14: 20 | P14: 2 | Z14: =$I14*($AO14+IF($L14="",VorgabeNotar,$L14)+IF($M14="",VorgabeMakler,$M14))/100+$N14 | AA14: =$I14+$Z14 | AB14: =$I14*$O14/100 | AC14: =MAX(0,$AA14-$AB14)+$Q14 | AD14: =$AC14*$P14/100 | AE14: =IF($P14=0,0,100/$P14) | AF14: =(MAX(0,$R14-$S14)+$T14+$U14)*12+$V14 | AG14: =IF($X14="",SteuersatzEff,$X14*(1+(IF(Soli="Ja",5.5,0)+Kirchensteuer)/100)) | AH14: =IF(SUMIF(EhObj,$B14,EhFlaeche)>0,SUMIF(EhObj,$B14,EhFlaeche),$G14) | AI14: =IF($H14="",0,YEAR($H14)) | AJ14: =IF($H14="",1,MONTH($H14)) | AK14: =IF($C14="",0,1) | AL14: =(MAX(0,$R14-$S14)+$T14)*12+$V14 | AM14: =IF($U14>0,$U14*12,$I14*InstandProzent/100) | AN14: =IF($W14="",$I14,$W14) | AO14: =IF($K14<>"",$K14,IF($J14="",VorgabeGrESt,IFERROR(INDEX(GrEStSatz,MATCH($J14,Bundeslaender,0)),VorgabeGrESt)))
B15: 8 | O15: 20 | P15: 2 | Z15: =$I15*($AO15+IF($L15="",VorgabeNotar,$L15)+IF($M15="",VorgabeMakler,$M15))/100+$N15 | AA15: =$I15+$Z15 | AB15: =$I15*$O15/100 | AC15: =MAX(0,$AA15-$AB15)+$Q15 | AD15: =$AC15*$P15/100 | AE15: =IF($P15=0,0,100/$P15) | AF15: =(MAX(0,$R15-$S15)+$T15+$U15)*12+$V15 | AG15: =IF($X15="",SteuersatzEff,$X15*(1+(IF(Soli="Ja",5.5,0)+Kirchensteuer)/100)) | AH15: =IF(SUMIF(EhObj,$B15,EhFlaeche)>0,SUMIF(EhObj,$B15,EhFlaeche),$G15) | AI15: =IF($H15="",0,YEAR($H15)) | AJ15: =IF($H15="",1,MONTH($H15)) | AK15: =IF($C15="",0,1) | AL15: =(MAX(0,$R15-$S15)+$T15)*12+$V15 | AM15: =IF($U15>0,$U15*12,$I15*InstandProzent/100) | AN15: =IF($W15="",$I15,$W15) | AO15: =IF($K15<>"",$K15,IF($J15="",VorgabeGrESt,IFERROR(INDEX(GrEStSatz,MATCH($J15,Bundeslaender,0)),VorgabeGrESt)))
B16: 9 | O16: 20 | P16: 2 | Z16: =$I16*($AO16+IF($L16="",VorgabeNotar,$L16)+IF($M16="",VorgabeMakler,$M16))/100+$N16 | AA16: =$I16+$Z16 | AB16: =$I16*$O16/100 | AC16: =MAX(0,$AA16-$AB16)+$Q16 | AD16: =$AC16*$P16/100 | AE16: =IF($P16=0,0,100/$P16) | AF16: =(MAX(0,$R16-$S16)+$T16+$U16)*12+$V16 | AG16: =IF($X16="",SteuersatzEff,$X16*(1+(IF(Soli="Ja",5.5,0)+Kirchensteuer)/100)) | AH16: =IF(SUMIF(EhObj,$B16,EhFlaeche)>0,SUMIF(EhObj,$B16,EhFlaeche),$G16) | AI16: =IF($H16="",0,YEAR($H16)) | AJ16: =IF($H16="",1,MONTH($H16)) | AK16: =IF($C16="",0,1) | AL16: =(MAX(0,$R16-$S16)+$T16)*12+$V16 | AM16: =IF($U16>0,$U16*12,$I16*InstandProzent/100) | AN16: =IF($W16="",$I16,$W16) | AO16: =IF($K16<>"",$K16,IF($J16="",VorgabeGrESt,IFERROR(INDEX(GrEStSatz,MATCH($J16,Bundeslaender,0)),VorgabeGrESt)))
B17: 10 | O17: 20 | P17: 2 | Z17: =$I17*($AO17+IF($L17="",VorgabeNotar,$L17)+IF($M17="",VorgabeMakler,$M17))/100+$N17 | AA17: =$I17+$Z17 | AB17: =$I17*$O17/100 | AC17: =MAX(0,$AA17-$AB17)+$Q17 | AD17: =$AC17*$P17/100 | AE17: =IF($P17=0,0,100/$P17) | AF17: =(MAX(0,$R17-$S17)+$T17+$U17)*12+$V17 | AG17: =IF($X17="",SteuersatzEff,$X17*(1+(IF(Soli="Ja",5.5,0)+Kirchensteuer)/100)) | AH17: =IF(SUMIF(EhObj,$B17,EhFlaeche)>0,SUMIF(EhObj,$B17,EhFlaeche),$G17) | AI17: =IF($H17="",0,YEAR($H17)) | AJ17: =IF($H17="",1,MONTH($H17)) | AK17: =IF($C17="",0,1) | AL17: =(MAX(0,$R17-$S17)+$T17)*12+$V17 | AM17: =IF($U17>0,$U17*12,$I17*InstandProzent/100) | AN17: =IF($W17="",$I17,$W17) | AO17: =IF($K17<>"",$K17,IF($J17="",VorgabeGrESt,IFERROR(INDEX(GrEStSatz,MATCH($J17,Bundeslaender,0)),VorgabeGrESt)))
B20: B · Einheiten | E20: Ein Objekt mit nur einer Wohnung braucht trotzdem eine Zeile – die Mietverträge hängen daran.
B21: Nr | C21: Objekt | D21: Bezeichnung | E21: Fläche m² | F21: Zimmer
B22: 1 | AP22: =IFERROR(MATCH($C22,ObjBezeichnung,0),0) | AQ22: =IF(COUNTIFS(MvEinheitNr,$B22,MvAktiv,1)>0,1,0) | AR22: =IF($D22="","",$D22&" ("&$C22&")")
B23: 2 | AP23: =IFERROR(MATCH($C23,ObjBezeichnung,0),0) | AQ23: =IF(COUNTIFS(MvEinheitNr,$B23,MvAktiv,1)>0,1,0) | AR23: =IF($D23="","",$D23&" ("&$C23&")")
B24: 3 | AP24: =IFERROR(MATCH($C24,ObjBezeichnung,0),0) | AQ24: =IF(COUNTIFS(MvEinheitNr,$B24,MvAktiv,1)>0,1,0) | AR24: =IF($D24="","",$D24&" ("&$C24&")")
B25: 4 | AP25: =IFERROR(MATCH($C25,ObjBezeichnung,0),0) | AQ25: =IF(COUNTIFS(MvEinheitNr,$B25,MvAktiv,1)>0,1,0) | AR25: =IF($D25="","",$D25&" ("&$C25&")")
B26: 5 | AP26: =IFERROR(MATCH($C26,ObjBezeichnung,0),0) | AQ26: =IF(COUNTIFS(MvEinheitNr,$B26,MvAktiv,1)>0,1,0) | AR26: =IF($D26="","",$D26&" ("&$C26&")")
B27: 6 | AP27: =IFERROR(MATCH($C27,ObjBezeichnung,0),0) | AQ27: =IF(COUNTIFS(MvEinheitNr,$B27,MvAktiv,1)>0,1,0) | AR27: =IF($D27="","",$D27&" ("&$C27&")")
B28: 7 | AP28: =IFERROR(MATCH($C28,ObjBezeichnung,0),0) | AQ28: =IF(COUNTIFS(MvEinheitNr,$B28,MvAktiv,1)>0,1,0) | AR28: =IF($D28="","",$D28&" ("&$C28&")")
B29: 8 | AP29: =IFERROR(MATCH($C29,ObjBezeichnung,0),0) | AQ29: =IF(COUNTIFS(MvEinheitNr,$B29,MvAktiv,1)>0,1,0) | AR29: =IF($D29="","",$D29&" ("&$C29&")")
B30: 9 | AP30: =IFERROR(MATCH($C30,ObjBezeichnung,0),0) | AQ30: =IF(COUNTIFS(MvEinheitNr,$B30,MvAktiv,1)>0,1,0) | AR30: =IF($D30="","",$D30&" ("&$C30&")")
B31: 10 | AP31: =IFERROR(MATCH($C31,ObjBezeichnung,0),0) | AQ31: =IF(COUNTIFS(MvEinheitNr,$B31,MvAktiv,1)>0,1,0) | AR31: =IF($D31="","",$D31&" ("&$C31&")")
B32: 11 | AP32: =IFERROR(MATCH($C32,ObjBezeichnung,0),0) | AQ32: =IF(COUNTIFS(MvEinheitNr,$B32,MvAktiv,1)>0,1,0) | AR32: =IF($D32="","",$D32&" ("&$C32&")")
B33: 12 | AP33: =IFERROR(MATCH($C33,ObjBezeichnung,0),0) | AQ33: =IF(COUNTIFS(MvEinheitNr,$B33,MvAktiv,1)>0,1,0) | AR33: =IF($D33="","",$D33&" ("&$C33&")")
... B51: 30 | AP51: =IFERROR(MATCH($C51,ObjBezeichnung,0),0) | AQ51: =IF(COUNTIFS(MvEinheitNr,$B51,MvAktiv,1)>0,1,0) | AR51: =IF($D51="","",$D51&" ("&$C51&")")
B54: ="C · Kennzahlen je Objekt zum "&TEXT(DAY(Stichtag),"00")&"."&TEXT(MONTH(Stichtag),"00")&"."&YEAR(Stichtag) | H54: gerechnet – hier wird nichts eingetragen
B55: Nr | C55: Bezeichnung | D55: Investition | E55: Verkehrswert | F55: Restschuld | G55: Kaltmiete/M | H55: Brutto­rendite | I55: Netto­rendite | J55: Kaufpreis­faktor | K55: €/m² | L55: Beleihung | M55: DSCR | N55: CF/M vor St. | O55: CF/M nach St. | P55: EK-Rendite
B56: 1 | C56: =IF(INDEX(ObjBelegt,1)=0,"–",INDEX(ObjBezeichnung,1)) | D56: =IF(INDEX(ObjBelegt,1)=0,"",INDEX(IstInvest,1)) | E56: =IF(INDEX(ObjBelegt,1)=0,"",INDEX(IstWert,1)) | F56: =IF(INDEX(ObjBelegt,1)=0,"",INDEX(IstRest,1)) | G56: =IF(INDEX(ObjBelegt,1)=0,"",INDEX(IstMieteMonat,1)) | H56: =IF(INDEX(ObjBelegt,1)=0,"",IF(INDEX(IstInvest,1)=0,0,INDEX(IstRunrate,1)/INDEX(IstInvest,1)*100)) | I56: =IF(INDEX(ObjBelegt,1)=0,"",IF(INDEX(IstInvest,1)=0,0,(INDEX(IstRunrate,1)-INDEX(IstBewirtVoll,1))/INDEX(IstInvest,1)*100)) | J56: =IF(INDEX(ObjBelegt,1)=0,"",IF(INDEX(IstRunrate,1)=0,0,INDEX(ObjKaufpreis,1)/INDEX(IstRunrate,1))) | K56: =IF(INDEX(ObjBelegt,1)=0,"",IF(INDEX(IstFlaeche,1)=0,0,INDEX(IstMieteMonat,1)/INDEX(IstFlaeche,1))) | L56: =IF(INDEX(ObjBelegt,1)=0,"",IF(INDEX(IstWert,1)=0,0,INDEX(IstRest,1)/INDEX(IstWert,1)*100)) | M56: =IF(INDEX(ObjBelegt,1)=0,"",IF(INDEX(IstKapital12,1)=0,0,(INDEX(IstRunrate,1)-INDEX(IstBewirtVoll,1))/INDEX(IstKapital12,1))) | N56: =IF(INDEX(ObjBelegt,1)=0,"",INDEX(IstCfVor,1)/12) | O56: =IF(INDEX(ObjBelegt,1)=0,"",INDEX(IstCfNach,1)/12) | P56: =IF(INDEX(ObjBelegt,1)=0,"",IF(INDEX(IstEkEingesetzt,1)=0,0,INDEX(IstCfRunrateNach,1)/INDEX(IstEkEingesetzt,1)*100))
B57: 2 | C57: =IF(INDEX(ObjBelegt,2)=0,"–",INDEX(ObjBezeichnung,2)) | D57: =IF(INDEX(ObjBelegt,2)=0,"",INDEX(IstInvest,2)) | E57: =IF(INDEX(ObjBelegt,2)=0,"",INDEX(IstWert,2)) | F57: =IF(INDEX(ObjBelegt,2)=0,"",INDEX(IstRest,2)) | G57: =IF(INDEX(ObjBelegt,2)=0,"",INDEX(IstMieteMonat,2)) | H57: =IF(INDEX(ObjBelegt,2)=0,"",IF(INDEX(IstInvest,2)=0,0,INDEX(IstRunrate,2)/INDEX(IstInvest,2)*100)) | I57: =IF(INDEX(ObjBelegt,2)=0,"",IF(INDEX(IstInvest,2)=0,0,(INDEX(IstRunrate,2)-INDEX(IstBewirtVoll,2))/INDEX(IstInvest,2)*100)) | J57: =IF(INDEX(ObjBelegt,2)=0,"",IF(INDEX(IstRunrate,2)=0,0,INDEX(ObjKaufpreis,2)/INDEX(IstRunrate,2))) | K57: =IF(INDEX(ObjBelegt,2)=0,"",IF(INDEX(IstFlaeche,2)=0,0,INDEX(IstMieteMonat,2)/INDEX(IstFlaeche,2))) | L57: =IF(INDEX(ObjBelegt,2)=0,"",IF(INDEX(IstWert,2)=0,0,INDEX(IstRest,2)/INDEX(IstWert,2)*100)) | M57: =IF(INDEX(ObjBelegt,2)=0,"",IF(INDEX(IstKapital12,2)=0,0,(INDEX(IstRunrate,2)-INDEX(IstBewirtVoll,2))/INDEX(IstKapital12,2))) | N57: =IF(INDEX(ObjBelegt,2)=0,"",INDEX(IstCfVor,2)/12) | O57: =IF(INDEX(ObjBelegt,2)=0,"",INDEX(IstCfNach,2)/12) | P57: =IF(INDEX(ObjBelegt,2)=0,"",IF(INDEX(IstEkEingesetzt,2)=0,0,INDEX(IstCfRunrateNach,2)/INDEX(IstEkEingesetzt,2)*100))
B58: 3 | C58: =IF(INDEX(ObjBelegt,3)=0,"–",INDEX(ObjBezeichnung,3)) | D58: =IF(INDEX(ObjBelegt,3)=0,"",INDEX(IstInvest,3)) | E58: =IF(INDEX(ObjBelegt,3)=0,"",INDEX(IstWert,3)) | F58: =IF(INDEX(ObjBelegt,3)=0,"",INDEX(IstRest,3)) | G58: =IF(INDEX(ObjBelegt,3)=0,"",INDEX(IstMieteMonat,3)) | H58: =IF(INDEX(ObjBelegt,3)=0,"",IF(INDEX(IstInvest,3)=0,0,INDEX(IstRunrate,3)/INDEX(IstInvest,3)*100)) | I58: =IF(INDEX(ObjBelegt,3)=0,"",IF(INDEX(IstInvest,3)=0,0,(INDEX(IstRunrate,3)-INDEX(IstBewirtVoll,3))/INDEX(IstInvest,3)*100)) | J58: =IF(INDEX(ObjBelegt,3)=0,"",IF(INDEX(IstRunrate,3)=0,0,INDEX(ObjKaufpreis,3)/INDEX(IstRunrate,3))) | K58: =IF(INDEX(ObjBelegt,3)=0,"",IF(INDEX(IstFlaeche,3)=0,0,INDEX(IstMieteMonat,3)/INDEX(IstFlaeche,3))) | L58: =IF(INDEX(ObjBelegt,3)=0,"",IF(INDEX(IstWert,3)=0,0,INDEX(IstRest,3)/INDEX(IstWert,3)*100)) | M58: =IF(INDEX(ObjBelegt,3)=0,"",IF(INDEX(IstKapital12,3)=0,0,(INDEX(IstRunrate,3)-INDEX(IstBewirtVoll,3))/INDEX(IstKapital12,3))) | N58: =IF(INDEX(ObjBelegt,3)=0,"",INDEX(IstCfVor,3)/12) | O58: =IF(INDEX(ObjBelegt,3)=0,"",INDEX(IstCfNach,3)/12) | P58: =IF(INDEX(ObjBelegt,3)=0,"",IF(INDEX(IstEkEingesetzt,3)=0,0,INDEX(IstCfRunrateNach,3)/INDEX(IstEkEingesetzt,3)*100))
B59: 4 | C59: =IF(INDEX(ObjBelegt,4)=0,"–",INDEX(ObjBezeichnung,4)) | D59: =IF(INDEX(ObjBelegt,4)=0,"",INDEX(IstInvest,4)) | E59: =IF(INDEX(ObjBelegt,4)=0,"",INDEX(IstWert,4)) | F59: =IF(INDEX(ObjBelegt,4)=0,"",INDEX(IstRest,4)) | G59: =IF(INDEX(ObjBelegt,4)=0,"",INDEX(IstMieteMonat,4)) | H59: =IF(INDEX(ObjBelegt,4)=0,"",IF(INDEX(IstInvest,4)=0,0,INDEX(IstRunrate,4)/INDEX(IstInvest,4)*100)) | I59: =IF(INDEX(ObjBelegt,4)=0,"",IF(INDEX(IstInvest,4)=0,0,(INDEX(IstRunrate,4)-INDEX(IstBewirtVoll,4))/INDEX(IstInvest,4)*100)) | J59: =IF(INDEX(ObjBelegt,4)=0,"",IF(INDEX(IstRunrate,4)=0,0,INDEX(ObjKaufpreis,4)/INDEX(IstRunrate,4))) | K59: =IF(INDEX(ObjBelegt,4)=0,"",IF(INDEX(IstFlaeche,4)=0,0,INDEX(IstMieteMonat,4)/INDEX(IstFlaeche,4))) | L59: =IF(INDEX(ObjBelegt,4)=0,"",IF(INDEX(IstWert,4)=0,0,INDEX(IstRest,4)/INDEX(IstWert,4)*100)) | M59: =IF(INDEX(ObjBelegt,4)=0,"",IF(INDEX(IstKapital12,4)=0,0,(INDEX(IstRunrate,4)-INDEX(IstBewirtVoll,4))/INDEX(IstKapital12,4))) | N59: =IF(INDEX(ObjBelegt,4)=0,"",INDEX(IstCfVor,4)/12) | O59: =IF(INDEX(ObjBelegt,4)=0,"",INDEX(IstCfNach,4)/12) | P59: =IF(INDEX(ObjBelegt,4)=0,"",IF(INDEX(IstEkEingesetzt,4)=0,0,INDEX(IstCfRunrateNach,4)/INDEX(IstEkEingesetzt,4)*100))
B60: 5 | C60: =IF(INDEX(ObjBelegt,5)=0,"–",INDEX(ObjBezeichnung,5)) | D60: =IF(INDEX(ObjBelegt,5)=0,"",INDEX(IstInvest,5)) | E60: =IF(INDEX(ObjBelegt,5)=0,"",INDEX(IstWert,5)) | F60: =IF(INDEX(ObjBelegt,5)=0,"",INDEX(IstRest,5)) | G60: =IF(INDEX(ObjBelegt,5)=0,"",INDEX(IstMieteMonat,5)) | H60: =IF(INDEX(ObjBelegt,5)=0,"",IF(INDEX(IstInvest,5)=0,0,INDEX(IstRunrate,5)/INDEX(IstInvest,5)*100)) | I60: =IF(INDEX(ObjBelegt,5)=0,"",IF(INDEX(IstInvest,5)=0,0,(INDEX(IstRunrate,5)-INDEX(IstBewirtVoll,5))/INDEX(IstInvest,5)*100)) | J60: =IF(INDEX(ObjBelegt,5)=0,"",IF(INDEX(IstRunrate,5)=0,0,INDEX(ObjKaufpreis,5)/INDEX(IstRunrate,5))) | K60: =IF(INDEX(ObjBelegt,5)=0,"",IF(INDEX(IstFlaeche,5)=0,0,INDEX(IstMieteMonat,5)/INDEX(IstFlaeche,5))) | L60: =IF(INDEX(ObjBelegt,5)=0,"",IF(INDEX(IstWert,5)=0,0,INDEX(IstRest,5)/INDEX(IstWert,5)*100)) | M60: =IF(INDEX(ObjBelegt,5)=0,"",IF(INDEX(IstKapital12,5)=0,0,(INDEX(IstRunrate,5)-INDEX(IstBewirtVoll,5))/INDEX(IstKapital12,5))) | N60: =IF(INDEX(ObjBelegt,5)=0,"",INDEX(IstCfVor,5)/12) | O60: =IF(INDEX(ObjBelegt,5)=0,"",INDEX(IstCfNach,5)/12) | P60: =IF(INDEX(ObjBelegt,5)=0,"",IF(INDEX(IstEkEingesetzt,5)=0,0,INDEX(IstCfRunrateNach,5)/INDEX(IstEkEingesetzt,5)*100))
B61: 6 | C61: =IF(INDEX(ObjBelegt,6)=0,"–",INDEX(ObjBezeichnung,6)) | D61: =IF(INDEX(ObjBelegt,6)=0,"",INDEX(IstInvest,6)) | E61: =IF(INDEX(ObjBelegt,6)=0,"",INDEX(IstWert,6)) | F61: =IF(INDEX(ObjBelegt,6)=0,"",INDEX(IstRest,6)) | G61: =IF(INDEX(ObjBelegt,6)=0,"",INDEX(IstMieteMonat,6)) | H61: =IF(INDEX(ObjBelegt,6)=0,"",IF(INDEX(IstInvest,6)=0,0,INDEX(IstRunrate,6)/INDEX(IstInvest,6)*100)) | I61: =IF(INDEX(ObjBelegt,6)=0,"",IF(INDEX(IstInvest,6)=0,0,(INDEX(IstRunrate,6)-INDEX(IstBewirtVoll,6))/INDEX(IstInvest,6)*100)) | J61: =IF(INDEX(ObjBelegt,6)=0,"",IF(INDEX(IstRunrate,6)=0,0,INDEX(ObjKaufpreis,6)/INDEX(IstRunrate,6))) | K61: =IF(INDEX(ObjBelegt,6)=0,"",IF(INDEX(IstFlaeche,6)=0,0,INDEX(IstMieteMonat,6)/INDEX(IstFlaeche,6))) | L61: =IF(INDEX(ObjBelegt,6)=0,"",IF(INDEX(IstWert,6)=0,0,INDEX(IstRest,6)/INDEX(IstWert,6)*100)) | M61: =IF(INDEX(ObjBelegt,6)=0,"",IF(INDEX(IstKapital12,6)=0,0,(INDEX(IstRunrate,6)-INDEX(IstBewirtVoll,6))/INDEX(IstKapital12,6))) | N61: =IF(INDEX(ObjBelegt,6)=0,"",INDEX(IstCfVor,6)/12) | O61: =IF(INDEX(ObjBelegt,6)=0,"",INDEX(IstCfNach,6)/12) | P61: =IF(INDEX(ObjBelegt,6)=0,"",IF(INDEX(IstEkEingesetzt,6)=0,0,INDEX(IstCfRunrateNach,6)/INDEX(IstEkEingesetzt,6)*100))
B62: 7 | C62: =IF(INDEX(ObjBelegt,7)=0,"–",INDEX(ObjBezeichnung,7)) | D62: =IF(INDEX(ObjBelegt,7)=0,"",INDEX(IstInvest,7)) | E62: =IF(INDEX(ObjBelegt,7)=0,"",INDEX(IstWert,7)) | F62: =IF(INDEX(ObjBelegt,7)=0,"",INDEX(IstRest,7)) | G62: =IF(INDEX(ObjBelegt,7)=0,"",INDEX(IstMieteMonat,7)) | H62: =IF(INDEX(ObjBelegt,7)=0,"",IF(INDEX(IstInvest,7)=0,0,INDEX(IstRunrate,7)/INDEX(IstInvest,7)*100)) | I62: =IF(INDEX(ObjBelegt,7)=0,"",IF(INDEX(IstInvest,7)=0,0,(INDEX(IstRunrate,7)-INDEX(IstBewirtVoll,7))/INDEX(IstInvest,7)*100)) | J62: =IF(INDEX(ObjBelegt,7)=0,"",IF(INDEX(IstRunrate,7)=0,0,INDEX(ObjKaufpreis,7)/INDEX(IstRunrate,7))) | K62: =IF(INDEX(ObjBelegt,7)=0,"",IF(INDEX(IstFlaeche,7)=0,0,INDEX(IstMieteMonat,7)/INDEX(IstFlaeche,7))) | L62: =IF(INDEX(ObjBelegt,7)=0,"",IF(INDEX(IstWert,7)=0,0,INDEX(IstRest,7)/INDEX(IstWert,7)*100)) | M62: =IF(INDEX(ObjBelegt,7)=0,"",IF(INDEX(IstKapital12,7)=0,0,(INDEX(IstRunrate,7)-INDEX(IstBewirtVoll,7))/INDEX(IstKapital12,7))) | N62: =IF(INDEX(ObjBelegt,7)=0,"",INDEX(IstCfVor,7)/12) | O62: =IF(INDEX(ObjBelegt,7)=0,"",INDEX(IstCfNach,7)/12) | P62: =IF(INDEX(ObjBelegt,7)=0,"",IF(INDEX(IstEkEingesetzt,7)=0,0,INDEX(IstCfRunrateNach,7)/INDEX(IstEkEingesetzt,7)*100))
B63: 8 | C63: =IF(INDEX(ObjBelegt,8)=0,"–",INDEX(ObjBezeichnung,8)) | D63: =IF(INDEX(ObjBelegt,8)=0,"",INDEX(IstInvest,8)) | E63: =IF(INDEX(ObjBelegt,8)=0,"",INDEX(IstWert,8)) | F63: =IF(INDEX(ObjBelegt,8)=0,"",INDEX(IstRest,8)) | G63: =IF(INDEX(ObjBelegt,8)=0,"",INDEX(IstMieteMonat,8)) | H63: =IF(INDEX(ObjBelegt,8)=0,"",IF(INDEX(IstInvest,8)=0,0,INDEX(IstRunrate,8)/INDEX(IstInvest,8)*100)) | I63: =IF(INDEX(ObjBelegt,8)=0,"",IF(INDEX(IstInvest,8)=0,0,(INDEX(IstRunrate,8)-INDEX(IstBewirtVoll,8))/INDEX(IstInvest,8)*100)) | J63: =IF(INDEX(ObjBelegt,8)=0,"",IF(INDEX(IstRunrate,8)=0,0,INDEX(ObjKaufpreis,8)/INDEX(IstRunrate,8))) | K63: =IF(INDEX(ObjBelegt,8)=0,"",IF(INDEX(IstFlaeche,8)=0,0,INDEX(IstMieteMonat,8)/INDEX(IstFlaeche,8))) | L63: =IF(INDEX(ObjBelegt,8)=0,"",IF(INDEX(IstWert,8)=0,0,INDEX(IstRest,8)/INDEX(IstWert,8)*100)) | M63: =IF(INDEX(ObjBelegt,8)=0,"",IF(INDEX(IstKapital12,8)=0,0,(INDEX(IstRunrate,8)-INDEX(IstBewirtVoll,8))/INDEX(IstKapital12,8))) | N63: =IF(INDEX(ObjBelegt,8)=0,"",INDEX(IstCfVor,8)/12) | O63: =IF(INDEX(ObjBelegt,8)=0,"",INDEX(IstCfNach,8)/12) | P63: =IF(INDEX(ObjBelegt,8)=0,"",IF(INDEX(IstEkEingesetzt,8)=0,0,INDEX(IstCfRunrateNach,8)/INDEX(IstEkEingesetzt,8)*100))
...

Sheet Mietverträge
B2: ZAHLENKOMPASS
B3: Mietverträge
B4: Eine Zeile je Vertrag. Staffelmieten sind weitere Konditionen mit späterem "gilt ab".
B6: A · Verträge
B7: Nr | C7: Einheit | D7: Mieter | E7: Beginn | F7: befristet bis | G7: gekündigt zum | H7: Anpassung | I7: Index % p.a. | J7: gilt ab 1 | K7: kalt 1 | L7: NK 1 | M7: gilt ab 2 | N7: kalt 2 | O7: NK 2 | P7: gilt ab 3 | Q7: kalt 3 | R7: NK 3
B8: 1 | T8: =IFERROR(MATCH($C8,EhAnzeige,0),0) | U8: =IF($T8=0,0,INDEX(EhObj,$T8)) | V8: =IF(AND($F8="",$G8=""),0,IF($F8="",$G8,IF($G8="",$F8,MIN($F8,$G8)))) | W8: =IF(AND($H8="Index",$I8<>""),$I8,Mietsteigerung) | X8: =IF(OR($E8="",$E8>Stichtag),0,IF(AND($V8>0,$V8<Stichtag),0,1)) | Y8: =IF($X8=0,0,IF(Stichtag>=$AC8,$Q8,IF(Stichtag>=$AB8,$N8,IF(Stichtag>=$AA8,$K8,0)))) | Z8: =IF($X8=0,0,IF(Stichtag>=$AC8,$R8,IF(Stichtag>=$AB8,$O8,IF(Stichtag>=$AA8,$L8,0)))) | AA8: =IF($J8="",999999,$J8) | AB8: =IF($M8="",999999,$M8) | AC8: =IF($P8="",999999,$P8)
B9: 2 | T9: =IFERROR(MATCH($C9,EhAnzeige,0),0) | U9: =IF($T9=0,0,INDEX(EhObj,$T9)) | V9: =IF(AND($F9="",$G9=""),0,IF($F9="",$G9,IF($G9="",$F9,MIN($F9,$G9)))) | W9: =IF(AND($H9="Index",$I9<>""),$I9,Mietsteigerung) | X9: =IF(OR($E9="",$E9>Stichtag),0,IF(AND($V9>0,$V9<Stichtag),0,1)) | Y9: =IF($X9=0,0,IF(Stichtag>=$AC9,$Q9,IF(Stichtag>=$AB9,$N9,IF(Stichtag>=$AA9,$K9,0)))) | Z9: =IF($X9=0,0,IF(Stichtag>=$AC9,$R9,IF(Stichtag>=$AB9,$O9,IF(Stichtag>=$AA9,$L9,0)))) | AA9: =IF($J9="",999999,$J9) | AB9: =IF($M9="",999999,$M9) | AC9: =IF($P9="",999999,$P9)
B10: 3 | T10: =IFERROR(MATCH($C10,EhAnzeige,0),0) | U10: =IF($T10=0,0,INDEX(EhObj,$T10)) | V10: =IF(AND($F10="",$G10=""),0,IF($F10="",$G10,IF($G10="",$F10,MIN($F10,$G10)))) | W10: =IF(AND($H10="Index",$I10<>""),$I10,Mietsteigerung) | X10: =IF(OR($E10="",$E10>Stichtag),0,IF(AND($V10>0,$V10<Stichtag),0,1)) | Y10: =IF($X10=0,0,IF(Stichtag>=$AC10,$Q10,IF(Stichtag>=$AB10,$N10,IF(Stichtag>=$AA10,$K10,0)))) | Z10: =IF($X10=0,0,IF(Stichtag>=$AC10,$R10,IF(Stichtag>=$AB10,$O10,IF(Stichtag>=$AA10,$L10,0)))) | AA10: =IF($J10="",999999,$J10) | AB10: =IF($M10="",999999,$M10) | AC10: =IF($P10="",999999,$P10)
B11: 4 | T11: =IFERROR(MATCH($C11,EhAnzeige,0),0) | U11: =IF($T11=0,0,INDEX(EhObj,$T11)) | V11: =IF(AND($F11="",$G11=""),0,IF($F11="",$G11,IF($G11="",$F11,MIN($F11,$G11)))) | W11: =IF(AND($H11="Index",$I11<>""),$I11,Mietsteigerung) | X11: =IF(OR($E11="",$E11>Stichtag),0,IF(AND($V11>0,$V11<Stichtag),0,1)) | Y11: =IF($X11=0,0,IF(Stichtag>=$AC11,$Q11,IF(Stichtag>=$AB11,$N11,IF(Stichtag>=$AA11,$K11,0)))) | Z11: =IF($X11=0,0,IF(Stichtag>=$AC11,$R11,IF(Stichtag>=$AB11,$O11,IF(Stichtag>=$AA11,$L11,0)))) | AA11: =IF($J11="",999999,$J11) | AB11: =IF($M11="",999999,$M11) | AC11: =IF($P11="",999999,$P11)
B12: 5 | T12: =IFERROR(MATCH($C12,EhAnzeige,0),0) | U12: =IF($T12=0,0,INDEX(EhObj,$T12)) | V12: =IF(AND($F12="",$G12=""),0,IF($F12="",$G12,IF($G12="",$F12,MIN($F12,$G12)))) | W12: =IF(AND($H12="Index",$I12<>""),$I12,Mietsteigerung) | X12: =IF(OR($E12="",$E12>Stichtag),0,IF(AND($V12>0,$V12<Stichtag),0,1)) | Y12: =IF($X12=0,0,IF(Stichtag>=$AC12,$Q12,IF(Stichtag>=$AB12,$N12,IF(Stichtag>=$AA12,$K12,0)))) | Z12: =IF($X12=0,0,IF(Stichtag>=$AC12,$R12,IF(Stichtag>=$AB12,$O12,IF(Stichtag>=$AA12,$L12,0)))) | AA12: =IF($J12="",999999,$J12) | AB12: =IF($M12="",999999,$M12) | AC12: =IF($P12="",999999,$P12)
B13: 6 | T13: =IFERROR(MATCH($C13,EhAnzeige,0),0) | U13: =IF($T13=0,0,INDEX(EhObj,$T13)) | V13: =IF(AND($F13="",$G13=""),0,IF($F13="",$G13,IF($G13="",$F13,MIN($F13,$G13)))) | W13: =IF(AND($H13="Index",$I13<>""),$I13,Mietsteigerung) | X13: =IF(OR($E13="",$E13>Stichtag),0,IF(AND($V13>0,$V13<Stichtag),0,1)) | Y13: =IF($X13=0,0,IF(Stichtag>=$AC13,$Q13,IF(Stichtag>=$AB13,$N13,IF(Stichtag>=$AA13,$K13,0)))) | Z13: =IF($X13=0,0,IF(Stichtag>=$AC13,$R13,IF(Stichtag>=$AB13,$O13,IF(Stichtag>=$AA13,$L13,0)))) | AA13: =IF($J13="",999999,$J13) | AB13: =IF($M13="",999999,$M13) | AC13: =IF($P13="",999999,$P13)
B14: 7 | T14: =IFERROR(MATCH($C14,EhAnzeige,0),0) | U14: =IF($T14=0,0,INDEX(EhObj,$T14)) | V14: =IF(AND($F14="",$G14=""),0,IF($F14="",$G14,IF($G14="",$F14,MIN($F14,$G14)))) | W14: =IF(AND($H14="Index",$I14<>""),$I14,Mietsteigerung) | X14: =IF(OR($E14="",$E14>Stichtag),0,IF(AND($V14>0,$V14<Stichtag),0,1)) | Y14: =IF($X14=0,0,IF(Stichtag>=$AC14,$Q14,IF(Stichtag>=$AB14,$N14,IF(Stichtag>=$AA14,$K14,0)))) | Z14: =IF($X14=0,0,IF(Stichtag>=$AC14,$R14,IF(Stichtag>=$AB14,$O14,IF(Stichtag>=$AA14,$L14,0)))) | AA14: =IF($J14="",999999,$J14) | AB14: =IF($M14="",999999,$M14) | AC14: =IF($P14="",999999,$P14)
B15: 8 | T15: =IFERROR(MATCH($C15,EhAnzeige,0),0) | U15: =IF($T15=0,0,INDEX(EhObj,$T15)) | V15: =IF(AND($F15="",$G15=""),0,IF($F15="",$G15,IF($G15="",$F15,MIN($F15,$G15)))) | W15: =IF(AND($H15="Index",$I15<>""),$I15,Mietsteigerung) | X15: =IF(OR($E15="",$E15>Stichtag),0,IF(AND($V15>0,$V15<Stichtag),0,1)) | Y15: =IF($X15=0,0,IF(Stichtag>=$AC15,$Q15,IF(Stichtag>=$AB15,$N15,IF(Stichtag>=$AA15,$K15,0)))) | Z15: =IF($X15=0,0,IF(Stichtag>=$AC15,$R15,IF(Stichtag>=$AB15,$O15,IF(Stichtag>=$AA15,$L15,0)))) | AA15: =IF($J15="",999999,$J15) | AB15: =IF($M15="",999999,$M15) | AC15: =IF($P15="",999999,$P15)
B16: 9 | T16: =IFERROR(MATCH($C16,EhAnzeige,0),0) | U16: =IF($T16=0,0,INDEX(EhObj,$T16)) | V16: =IF(AND($F16="",$G16=""),0,IF($F16="",$G16,IF($G16="",$F16,MIN($F16,$G16)))) | W16: =IF(AND($H16="Index",$I16<>""),$I16,Mietsteigerung) | X16: =IF(OR($E16="",$E16>Stichtag),0,IF(AND($V16>0,$V16<Stichtag),0,1)) | Y16: =IF($X16=0,0,IF(Stichtag>=$AC16,$Q16,IF(Stichtag>=$AB16,$N16,IF(Stichtag>=$AA16,$K16,0)))) | Z16: =IF($X16=0,0,IF(Stichtag>=$AC16,$R16,IF(Stichtag>=$AB16,$O16,IF(Stichtag>=$AA16,$L16,0)))) | AA16: =IF($J16="",999999,$J16) | AB16: =IF($M16="",999999,$M16) | AC16: =IF($P16="",999999,$P16)
B17: 10 | T17: =IFERROR(MATCH($C17,EhAnzeige,0),0) | U17: =IF($T17=0,0,INDEX(EhObj,$T17)) | V17: =IF(AND($F17="",$G17=""),0,IF($F17="",$G17,IF($G17="",$F17,MIN($F17,$G17)))) | W17: =IF(AND($H17="Index",$I17<>""),$I17,Mietsteigerung) | X17: =IF(OR($E17="",$E17>Stichtag),0,IF(AND($V17>0,$V17<Stichtag),0,1)) | Y17: =IF($X17=0,0,IF(Stichtag>=$AC17,$Q17,IF(Stichtag>=$AB17,$N17,IF(Stichtag>=$AA17,$K17,0)))) | Z17: =IF($X17=0,0,IF(Stichtag>=$AC17,$R17,IF(Stichtag>=$AB17,$O17,IF(Stichtag>=$AA17,$L17,0)))) | AA17: =IF($J17="",999999,$J17) | AB17: =IF($M17="",999999,$M17) | AC17: =IF($P17="",999999,$P17)
B18: 11 | T18: =IFERROR(MATCH($C18,EhAnzeige,0),0) | U18: =IF($T18=0,0,INDEX(EhObj,$T18)) | V18: =IF(AND($F18="",$G18=""),0,IF($F18="",$G18,IF($G18="",$F18,MIN($F18,$G18)))) | W18: =IF(AND($H18="Index",$I18<>""),$I18,Mietsteigerung) | X18: =IF(OR($E18="",$E18>Stichtag),0,IF(AND($V18>0,$V18<Stichtag),0,1)) | Y18: =IF($X18=0,0,IF(Stichtag>=$AC18,$Q18,IF(Stichtag>=$AB18,$N18,IF(Stichtag>=$AA18,$K18,0)))) | Z18: =IF($X18=0,0,IF(Stichtag>=$AC18,$R18,IF(Stichtag>=$AB18,$O18,IF(Stichtag>=$AA18,$L18,0)))) | AA18: =IF($J18="",999999,$J18) | AB18: =IF($M18="",999999,$M18) | AC18: =IF($P18="",999999,$P18)
B19: 12 | T19: =IFERROR(MATCH($C19,EhAnzeige,0),0) | U19: =IF($T19=0,0,INDEX(EhObj,$T19)) | V19: =IF(AND($F19="",$G19=""),0,IF($F19="",$G19,IF($G19="",$F19,MIN($F19,$G19)))) | W19: =IF(AND($H19="Index",$I19<>""),$I19,Mietsteigerung) | X19: =IF(OR($E19="",$E19>Stichtag),0,IF(AND($V19>0,$V19<Stichtag),0,1)) | Y19: =IF($X19=0,0,IF(Stichtag>=$AC19,$Q19,IF(Stichtag>=$AB19,$N19,IF(Stichtag>=$AA19,$K19,0)))) | Z19: =IF($X19=0,0,IF(Stichtag>=$AC19,$R19,IF(Stichtag>=$AB19,$O19,IF(Stichtag>=$AA19,$L19,0)))) | AA19: =IF($J19="",999999,$J19) | AB19: =IF($M19="",999999,$M19) | AC19: =IF($P19="",999999,$P19)
... B37: 30 | T37: =IFERROR(MATCH($C37,EhAnzeige,0),0) | U37: =IF($T37=0,0,INDEX(EhObj,$T37)) | V37: =IF(AND($F37="",$G37=""),0,IF($F37="",$G37,IF($G37="",$F37,MIN($F37,$G37)))) | W37: =IF(AND($H37="Index",$I37<>""),$I37,Mietsteigerung) | X37: =IF(OR($E37="",$E37>Stichtag),0,IF(AND($V37>0,$V37<Stichtag),0,1)) | Y37: =IF($X37=0,0,IF(Stichtag>=$AC37,$Q37,IF(Stichtag>=$AB37,$N37,IF(Stichtag>=$AA37,$K37,0)))) | Z37: =IF($X37=0,0,IF(Stichtag>=$AC37,$R37,IF(Stichtag>=$AB37,$O37,IF(Stichtag>=$AA37,$L37,0)))) | AA37: =IF($J37="",999999,$J37) | AB37: =IF($M37="",999999,$M37) | AC37: =IF($P37="",999999,$P37)
B40: ="B · Miete je Objekt zum "&TEXT(DAY(Stichtag),"00")&"."&TEXT(MONTH(Stichtag),"00")&"."&YEAR(Stichtag)
B41: Nr | C41: Objekt | D41: Einheiten | E41: vermietet | F41: leer | G41: Kaltmiete/M | H41: NK/M | I41: Warmmiete/M | J41: €/m²
B42: 1 | C42: =IF(INDEX(ObjBelegt,1)=0,"–",INDEX(ObjBezeichnung,1)) | D42: =IF(INDEX(ObjBelegt,1)=0,"",INDEX(IstEinheiten,1)) | E42: =IF(INDEX(ObjBelegt,1)=0,"",INDEX(IstVermietet,1)) | F42: =IF(INDEX(ObjBelegt,1)=0,"",INDEX(IstLeerstand,1)) | G42: =IF(INDEX(ObjBelegt,1)=0,"",INDEX(IstMieteMonat,1)) | H42: =IF(INDEX(ObjBelegt,1)=0,"",INDEX(IstNkMonat,1)) | I42: =IF(INDEX(ObjBelegt,1)=0,"",INDEX(IstMieteMonat,1)+INDEX(IstNkMonat,1)) | J42: =IF(INDEX(ObjBelegt,1)=0,"",IF(INDEX(IstFlaeche,1)=0,0,INDEX(IstMieteMonat,1)/INDEX(IstFlaeche,1)))
B43: 2 | C43: =IF(INDEX(ObjBelegt,2)=0,"–",INDEX(ObjBezeichnung,2)) | D43: =IF(INDEX(ObjBelegt,2)=0,"",INDEX(IstEinheiten,2)) | E43: =IF(INDEX(ObjBelegt,2)=0,"",INDEX(IstVermietet,2)) | F43: =IF(INDEX(ObjBelegt,2)=0,"",INDEX(IstLeerstand,2)) | G43: =IF(INDEX(ObjBelegt,2)=0,"",INDEX(IstMieteMonat,2)) | H43: =IF(INDEX(ObjBelegt,2)=0,"",INDEX(IstNkMonat,2)) | I43: =IF(INDEX(ObjBelegt,2)=0,"",INDEX(IstMieteMonat,2)+INDEX(IstNkMonat,2)) | J43: =IF(INDEX(ObjBelegt,2)=0,"",IF(INDEX(IstFlaeche,2)=0,0,INDEX(IstMieteMonat,2)/INDEX(IstFlaeche,2)))
B44: 3 | C44: =IF(INDEX(ObjBelegt,3)=0,"–",INDEX(ObjBezeichnung,3)) | D44: =IF(INDEX(ObjBelegt,3)=0,"",INDEX(IstEinheiten,3)) | E44: =IF(INDEX(ObjBelegt,3)=0,"",INDEX(IstVermietet,3)) | F44: =IF(INDEX(ObjBelegt,3)=0,"",INDEX(IstLeerstand,3)) | G44: =IF(INDEX(ObjBelegt,3)=0,"",INDEX(IstMieteMonat,3)) | H44: =IF(INDEX(ObjBelegt,3)=0,"",INDEX(IstNkMonat,3)) | I44: =IF(INDEX(ObjBelegt,3)=0,"",INDEX(IstMieteMonat,3)+INDEX(IstNkMonat,3)) | J44: =IF(INDEX(ObjBelegt,3)=0,"",IF(INDEX(IstFlaeche,3)=0,0,INDEX(IstMieteMonat,3)/INDEX(IstFlaeche,3)))
B45: 4 | C45: =IF(INDEX(ObjBelegt,4)=0,"–",INDEX(ObjBezeichnung,4)) | D45: =IF(INDEX(ObjBelegt,4)=0,"",INDEX(IstEinheiten,4)) | E45: =IF(INDEX(ObjBelegt,4)=0,"",INDEX(IstVermietet,4)) | F45: =IF(INDEX(ObjBelegt,4)=0,"",INDEX(IstLeerstand,4)) | G45: =IF(INDEX(ObjBelegt,4)=0,"",INDEX(IstMieteMonat,4)) | H45: =IF(INDEX(ObjBelegt,4)=0,"",INDEX(IstNkMonat,4)) | I45: =IF(INDEX(ObjBelegt,4)=0,"",INDEX(IstMieteMonat,4)+INDEX(IstNkMonat,4)) | J45: =IF(INDEX(ObjBelegt,4)=0,"",IF(INDEX(IstFlaeche,4)=0,0,INDEX(IstMieteMonat,4)/INDEX(IstFlaeche,4)))
B46: 5 | C46: =IF(INDEX(ObjBelegt,5)=0,"–",INDEX(ObjBezeichnung,5)) | D46: =IF(INDEX(ObjBelegt,5)=0,"",INDEX(IstEinheiten,5)) | E46: =IF(INDEX(ObjBelegt,5)=0,"",INDEX(IstVermietet,5)) | F46: =IF(INDEX(ObjBelegt,5)=0,"",INDEX(IstLeerstand,5)) | G46: =IF(INDEX(ObjBelegt,5)=0,"",INDEX(IstMieteMonat,5)) | H46: =IF(INDEX(ObjBelegt,5)=0,"",INDEX(IstNkMonat,5)) | I46: =IF(INDEX(ObjBelegt,5)=0,"",INDEX(IstMieteMonat,5)+INDEX(IstNkMonat,5)) | J46: =IF(INDEX(ObjBelegt,5)=0,"",IF(INDEX(IstFlaeche,5)=0,0,INDEX(IstMieteMonat,5)/INDEX(IstFlaeche,5)))
B47: 6 | C47: =IF(INDEX(ObjBelegt,6)=0,"–",INDEX(ObjBezeichnung,6)) | D47: =IF(INDEX(ObjBelegt,6)=0,"",INDEX(IstEinheiten,6)) | E47: =IF(INDEX(ObjBelegt,6)=0,"",INDEX(IstVermietet,6)) | F47: =IF(INDEX(ObjBelegt,6)=0,"",INDEX(IstLeerstand,6)) | G47: =IF(INDEX(ObjBelegt,6)=0,"",INDEX(IstMieteMonat,6)) | H47: =IF(INDEX(ObjBelegt,6)=0,"",INDEX(IstNkMonat,6)) | I47: =IF(INDEX(ObjBelegt,6)=0,"",INDEX(IstMieteMonat,6)+INDEX(IstNkMonat,6)) | J47: =IF(INDEX(ObjBelegt,6)=0,"",IF(INDEX(IstFlaeche,6)=0,0,INDEX(IstMieteMonat,6)/INDEX(IstFlaeche,6)))
B48: 7 | C48: =IF(INDEX(ObjBelegt,7)=0,"–",INDEX(ObjBezeichnung,7)) | D48: =IF(INDEX(ObjBelegt,7)=0,"",INDEX(IstEinheiten,7)) | E48: =IF(INDEX(ObjBelegt,7)=0,"",INDEX(IstVermietet,7)) | F48: =IF(INDEX(ObjBelegt,7)=0,"",INDEX(IstLeerstand,7)) | G48: =IF(INDEX(ObjBelegt,7)=0,"",INDEX(IstMieteMonat,7)) | H48: =IF(INDEX(ObjBelegt,7)=0,"",INDEX(IstNkMonat,7)) | I48: =IF(INDEX(ObjBelegt,7)=0,"",INDEX(IstMieteMonat,7)+INDEX(IstNkMonat,7)) | J48: =IF(INDEX(ObjBelegt,7)=0,"",IF(INDEX(IstFlaeche,7)=0,0,INDEX(IstMieteMonat,7)/INDEX(IstFlaeche,7)))
B49: 8 | C49: =IF(INDEX(ObjBelegt,8)=0,"–",INDEX(ObjBezeichnung,8)) | D49: =IF(INDEX(ObjBelegt,8)=0,"",INDEX(IstEinheiten,8)) | E49: =IF(INDEX(ObjBelegt,8)=0,"",INDEX(IstVermietet,8)) | F49: =IF(INDEX(ObjBelegt,8)=0,"",INDEX(IstLeerstand,8)) | G49: =IF(INDEX(ObjBelegt,8)=0,"",INDEX(IstMieteMonat,8)) | H49: =IF(INDEX(ObjBelegt,8)=0,"",INDEX(IstNkMonat,8)) | I49: =IF(INDEX(ObjBelegt,8)=0,"",INDEX(IstMieteMonat,8)+INDEX(IstNkMonat,8)) | J49: =IF(INDEX(ObjBelegt,8)=0,"",IF(INDEX(IstFlaeche,8)=0,0,INDEX(IstMieteMonat,8)/INDEX(IstFlaeche,8)))
B50: 9 | C50: =IF(INDEX(ObjBelegt,9)=0,"–",INDEX(ObjBezeichnung,9)) | D50: =IF(INDEX(ObjBelegt,9)=0,"",INDEX(IstEinheiten,9)) | E50: =IF(INDEX(ObjBelegt,9)=0,"",INDEX(IstVermietet,9)) | F50: =IF(INDEX(ObjBelegt,9)=0,"",INDEX(IstLeerstand,9)) | G50: =IF(INDEX(ObjBelegt,9)=0,"",INDEX(IstMieteMonat,9)) | H50: =IF(INDEX(ObjBelegt,9)=0,"",INDEX(IstNkMonat,9)) | I50: =IF(INDEX(ObjBelegt,9)=0,"",INDEX(IstMieteMonat,9)+INDEX(IstNkMonat,9)) | J50: =IF(INDEX(ObjBelegt,9)=0,"",IF(INDEX(IstFlaeche,9)=0,0,INDEX(IstMieteMonat,9)/INDEX(IstFlaeche,9)))
B51: 10 | C51: =IF(INDEX(ObjBelegt,10)=0,"–",INDEX(ObjBezeichnung,10)) | D51: =IF(INDEX(ObjBelegt,10)=0,"",INDEX(IstEinheiten,10)) | E51: =IF(INDEX(ObjBelegt,10)=0,"",INDEX(IstVermietet,10)) | F51: =IF(INDEX(ObjBelegt,10)=0,"",INDEX(IstLeerstand,10)) | G51: =IF(INDEX(ObjBelegt,10)=0,"",INDEX(IstMieteMonat,10)) | H51: =IF(INDEX(ObjBelegt,10)=0,"",INDEX(IstNkMonat,10)) | I51: =IF(INDEX(ObjBelegt,10)=0,"",INDEX(IstMieteMonat,10)+INDEX(IstNkMonat,10)) | J51: =IF(INDEX(ObjBelegt,10)=0,"",IF(INDEX(IstFlaeche,10)=0,0,INDEX(IstMieteMonat,10)/INDEX(IstFlaeche,10)))

Sheet Darlehen
B2: ZAHLENKOMPASS
B3: Darlehen
B4: Nachschüssige Annuität, monatlich verrechnet. Die erste Rate fällt im Monat nach der Auszahlung an.
B6: A · Darlehen
B7: Nr | C7: Objekt | D7: Bank | E7: Art | F7: Betrag | G7: Auszahlung | H7: Sollzins % | I7: Tilgung % | J7: Zinsbindung bis | K7: eig. Anschluss % | L7: Tilgungsstart | M7: Tilgungsersatz | N7: Ersatz % p.a. | O7: Verzinsung % | P7: Sondertilgung % p.a.
B8: 1 | P8: 5 | R8: =IFERROR(MATCH($C8,ObjBezeichnung,0),0) | S8: =IF(OR($E8="Endfällig",$M8="Ja"),1,0) | T8: =IF($K8="",Anschlusszins,$K8) | U8: =IF(OR($L8="",$G8=""),0,DATE(YEAR($L8),MONTH($L8),1)) | V8: =IF($M8="Ja",$F8*$N8/100/12,0) | W8: =IF($M8="Ja",$O8/100/12,0) | X8: =IF($S8=1,0,$F8*($H8+$I8)/100/12) | Y8: =IF($F8="","",$B8&" · "&IF($D8="","Darlehen",$D8)) | Z8: =IF(OR($F8="",$F8=0,$G8=""),0,1) | AA8: =IF(AND($Z8=1,SUMIFS(TilgAktiv,TilgDarl,$B8)>=480,EOMONTH($G8,479)+1<DATE(Jahr+MIN(PrognoseJahre,30),12,1)),1,0)
B9: 2 | P9: 5 | R9: =IFERROR(MATCH($C9,ObjBezeichnung,0),0) | S9: =IF(OR($E9="Endfällig",$M9="Ja"),1,0) | T9: =IF($K9="",Anschlusszins,$K9) | U9: =IF(OR($L9="",$G9=""),0,DATE(YEAR($L9),MONTH($L9),1)) | V9: =IF($M9="Ja",$F9*$N9/100/12,0) | W9: =IF($M9="Ja",$O9/100/12,0) | X9: =IF($S9=1,0,$F9*($H9+$I9)/100/12) | Y9: =IF($F9="","",$B9&" · "&IF($D9="","Darlehen",$D9)) | Z9: =IF(OR($F9="",$F9=0,$G9=""),0,1) | AA9: =IF(AND($Z9=1,SUMIFS(TilgAktiv,TilgDarl,$B9)>=480,EOMONTH($G9,479)+1<DATE(Jahr+MIN(PrognoseJahre,30),12,1)),1,0)
B10: 3 | P10: 5 | R10: =IFERROR(MATCH($C10,ObjBezeichnung,0),0) | S10: =IF(OR($E10="Endfällig",$M10="Ja"),1,0) | T10: =IF($K10="",Anschlusszins,$K10) | U10: =IF(OR($L10="",$G10=""),0,DATE(YEAR($L10),MONTH($L10),1)) | V10: =IF($M10="Ja",$F10*$N10/100/12,0) | W10: =IF($M10="Ja",$O10/100/12,0) | X10: =IF($S10=1,0,$F10*($H10+$I10)/100/12) | Y10: =IF($F10="","",$B10&" · "&IF($D10="","Darlehen",$D10)) | Z10: =IF(OR($F10="",$F10=0,$G10=""),0,1) | AA10: =IF(AND($Z10=1,SUMIFS(TilgAktiv,TilgDarl,$B10)>=480,EOMONTH($G10,479)+1<DATE(Jahr+MIN(PrognoseJahre,30),12,1)),1,0)
B11: 4 | P11: 5 | R11: =IFERROR(MATCH($C11,ObjBezeichnung,0),0) | S11: =IF(OR($E11="Endfällig",$M11="Ja"),1,0) | T11: =IF($K11="",Anschlusszins,$K11) | U11: =IF(OR($L11="",$G11=""),0,DATE(YEAR($L11),MONTH($L11),1)) | V11: =IF($M11="Ja",$F11*$N11/100/12,0) | W11: =IF($M11="Ja",$O11/100/12,0) | X11: =IF($S11=1,0,$F11*($H11+$I11)/100/12) | Y11: =IF($F11="","",$B11&" · "&IF($D11="","Darlehen",$D11)) | Z11: =IF(OR($F11="",$F11=0,$G11=""),0,1) | AA11: =IF(AND($Z11=1,SUMIFS(TilgAktiv,TilgDarl,$B11)>=480,EOMONTH($G11,479)+1<DATE(Jahr+MIN(PrognoseJahre,30),12,1)),1,0)
B12: 5 | P12: 5 | R12: =IFERROR(MATCH($C12,ObjBezeichnung,0),0) | S12: =IF(OR($E12="Endfällig",$M12="Ja"),1,0) | T12: =IF($K12="",Anschlusszins,$K12) | U12: =IF(OR($L12="",$G12=""),0,DATE(YEAR($L12),MONTH($L12),1)) | V12: =IF($M12="Ja",$F12*$N12/100/12,0) | W12: =IF($M12="Ja",$O12/100/12,0) | X12: =IF($S12=1,0,$F12*($H12+$I12)/100/12) | Y12: =IF($F12="","",$B12&" · "&IF($D12="","Darlehen",$D12)) | Z12: =IF(OR($F12="",$F12=0,$G12=""),0,1) | AA12: =IF(AND($Z12=1,SUMIFS(TilgAktiv,TilgDarl,$B12)>=480,EOMONTH($G12,479)+1<DATE(Jahr+MIN(PrognoseJahre,30),12,1)),1,0)
B13: 6 | P13: 5 | R13: =IFERROR(MATCH($C13,ObjBezeichnung,0),0) | S13: =IF(OR($E13="Endfällig",$M13="Ja"),1,0) | T13: =IF($K13="",Anschlusszins,$K13) | U13: =IF(OR($L13="",$G13=""),0,DATE(YEAR($L13),MONTH($L13),1)) | V13: =IF($M13="Ja",$F13*$N13/100/12,0) | W13: =IF($M13="Ja",$O13/100/12,0) | X13: =IF($S13=1,0,$F13*($H13+$I13)/100/12) | Y13: =IF($F13="","",$B13&" · "&IF($D13="","Darlehen",$D13)) | Z13: =IF(OR($F13="",$F13=0,$G13=""),0,1) | AA13: =IF(AND($Z13=1,SUMIFS(TilgAktiv,TilgDarl,$B13)>=480,EOMONTH($G13,479)+1<DATE(Jahr+MIN(PrognoseJahre,30),12,1)),1,0)
B14: 7 | P14: 5 | R14: =IFERROR(MATCH($C14,ObjBezeichnung,0),0) | S14: =IF(OR($E14="Endfällig",$M14="Ja"),1,0) | T14: =IF($K14="",Anschlusszins,$K14) | U14: =IF(OR($L14="",$G14=""),0,DATE(YEAR($L14),MONTH($L14),1)) | V14: =IF($M14="Ja",$F14*$N14/100/12,0) | W14: =IF($M14="Ja",$O14/100/12,0) | X14: =IF($S14=1,0,$F14*($H14+$I14)/100/12) | Y14: =IF($F14="","",$B14&" · "&IF($D14="","Darlehen",$D14)) | Z14: =IF(OR($F14="",$F14=0,$G14=""),0,1) | AA14: =IF(AND($Z14=1,SUMIFS(TilgAktiv,TilgDarl,$B14)>=480,EOMONTH($G14,479)+1<DATE(Jahr+MIN(PrognoseJahre,30),12,1)),1,0)
B15: 8 | P15: 5 | R15: =IFERROR(MATCH($C15,ObjBezeichnung,0),0) | S15: =IF(OR($E15="Endfällig",$M15="Ja"),1,0) | T15: =IF($K15="",Anschlusszins,$K15) | U15: =IF(OR($L15="",$G15=""),0,DATE(YEAR($L15),MONTH($L15),1)) | V15: =IF($M15="Ja",$F15*$N15/100/12,0) | W15: =IF($M15="Ja",$O15/100/12,0) | X15: =IF($S15=1,0,$F15*($H15+$I15)/100/12) | Y15: =IF($F15="","",$B15&" · "&IF($D15="","Darlehen",$D15)) | Z15: =IF(OR($F15="",$F15=0,$G15=""),0,1) | AA15: =IF(AND($Z15=1,SUMIFS(TilgAktiv,TilgDarl,$B15)>=480,EOMONTH($G15,479)+1<DATE(Jahr+MIN(PrognoseJahre,30),12,1)),1,0)
B16: 9 | P16: 5 | R16: =IFERROR(MATCH($C16,ObjBezeichnung,0),0) | S16: =IF(OR($E16="Endfällig",$M16="Ja"),1,0) | T16: =IF($K16="",Anschlusszins,$K16) | U16: =IF(OR($L16="",$G16=""),0,DATE(YEAR($L16),MONTH($L16),1)) | V16: =IF($M16="Ja",$F16*$N16/100/12,0) | W16: =IF($M16="Ja",$O16/100/12,0) | X16: =IF($S16=1,0,$F16*($H16+$I16)/100/12) | Y16: =IF($F16="","",$B16&" · "&IF($D16="","Darlehen",$D16)) | Z16: =IF(OR($F16="",$F16=0,$G16=""),0,1) | AA16: =IF(AND($Z16=1,SUMIFS(TilgAktiv,TilgDarl,$B16)>=480,EOMONTH($G16,479)+1<DATE(Jahr+MIN(PrognoseJahre,30),12,1)),1,0)
B17: 10 | P17: 5 | R17: =IFERROR(MATCH($C17,ObjBezeichnung,0),0) | S17: =IF(OR($E17="Endfällig",$M17="Ja"),1,0) | T17: =IF($K17="",Anschlusszins,$K17) | U17: =IF(OR($L17="",$G17=""),0,DATE(YEAR($L17),MONTH($L17),1)) | V17: =IF($M17="Ja",$F17*$N17/100/12,0) | W17: =IF($M17="Ja",$O17/100/12,0) | X17: =IF($S17=1,0,$F17*($H17+$I17)/100/12) | Y17: =IF($F17="","",$B17&" · "&IF($D17="","Darlehen",$D17)) | Z17: =IF(OR($F17="",$F17=0,$G17=""),0,1) | AA17: =IF(AND($Z17=1,SUMIFS(TilgAktiv,TilgDarl,$B17)>=480,EOMONTH($G17,479)+1<DATE(Jahr+MIN(PrognoseJahre,30),12,1)),1,0)
B18: 11 | P18: 5 | R18: =IFERROR(MATCH($C18,ObjBezeichnung,0),0) | S18: =IF(OR($E18="Endfällig",$M18="Ja"),1,0) | T18: =IF($K18="",Anschlusszins,$K18) | U18: =IF(OR($L18="",$G18=""),0,DATE(YEAR($L18),MONTH($L18),1)) | V18: =IF($M18="Ja",$F18*$N18/100/12,0) | W18: =IF($M18="Ja",$O18/100/12,0) | X18: =IF($S18=1,0,$F18*($H18+$I18)/100/12) | Y18: =IF($F18="","",$B18&" · "&IF($D18="","Darlehen",$D18)) | Z18: =IF(OR($F18="",$F18=0,$G18=""),0,1) | AA18: =IF(AND($Z18=1,SUMIFS(TilgAktiv,TilgDarl,$B18)>=480,EOMONTH($G18,479)+1<DATE(Jahr+MIN(PrognoseJahre,30),12,1)),1,0)
B19: 12 | P19: 5 | R19: =IFERROR(MATCH($C19,ObjBezeichnung,0),0) | S19: =IF(OR($E19="Endfällig",$M19="Ja"),1,0) | T19: =IF($K19="",Anschlusszins,$K19) | U19: =IF(OR($L19="",$G19=""),0,DATE(YEAR($L19),MONTH($L19),1)) | V19: =IF($M19="Ja",$F19*$N19/100/12,0) | W19: =IF($M19="Ja",$O19/100/12,0) | X19: =IF($S19=1,0,$F19*($H19+$I19)/100/12) | Y19: =IF($F19="","",$B19&" · "&IF($D19="","Darlehen",$D19)) | Z19: =IF(OR($F19="",$F19=0,$G19=""),0,1) | AA19: =IF(AND($Z19=1,SUMIFS(TilgAktiv,TilgDarl,$B19)>=480,EOMONTH($G19,479)+1<DATE(Jahr+MIN(PrognoseJahre,30),12,1)),1,0)
... B27: 20 | P27: 5 | R27: =IFERROR(MATCH($C27,ObjBezeichnung,0),0) | S27: =IF(OR($E27="Endfällig",$M27="Ja"),1,0) | T27: =IF($K27="",Anschlusszins,$K27) | U27: =IF(OR($L27="",$G27=""),0,DATE(YEAR($L27),MONTH($L27),1)) | V27: =IF($M27="Ja",$F27*$N27/100/12,0) | W27: =IF($M27="Ja",$O27/100/12,0) | X27: =IF($S27=1,0,$F27*($H27+$I27)/100/12) | Y27: =IF($F27="","",$B27&" · "&IF($D27="","Darlehen",$D27)) | Z27: =IF(OR($F27="",$F27=0,$G27=""),0,1) | AA27: =IF(AND($Z27=1,SUMIFS(TilgAktiv,TilgDarl,$B27)>=480,EOMONTH($G27,479)+1<DATE(Jahr+MIN(PrognoseJahre,30),12,1)),1,0)
B30: B · Sondertilgungen | E30: Werden im Monat des Datums verrechnet, höchstens bis zur Restschuld.
B31: Nr | C31: Darlehen | D31: Datum | E31: Betrag
B32: 1 | G32: =IFERROR(MATCH($C32,DarlAnzeige,0),0) | H32: =IF($D32="",0,YEAR($D32))
B33: 2 | G33: =IFERROR(MATCH($C33,DarlAnzeige,0),0) | H33: =IF($D33="",0,YEAR($D33))
B34: 3 | G34: =IFERROR(MATCH($C34,DarlAnzeige,0),0) | H34: =IF($D34="",0,YEAR($D34))
B35: 4 | G35: =IFERROR(MATCH($C35,DarlAnzeige,0),0) | H35: =IF($D35="",0,YEAR($D35))
B36: 5 | G36: =IFERROR(MATCH($C36,DarlAnzeige,0),0) | H36: =IF($D36="",0,YEAR($D36))
B37: 6 | G37: =IFERROR(MATCH($C37,DarlAnzeige,0),0) | H37: =IF($D37="",0,YEAR($D37))
B38: 7 | G38: =IFERROR(MATCH($C38,DarlAnzeige,0),0) | H38: =IF($D38="",0,YEAR($D38))
B39: 8 | G39: =IFERROR(MATCH($C39,DarlAnzeige,0),0) | H39: =IF($D39="",0,YEAR($D39))
B40: 9 | G40: =IFERROR(MATCH($C40,DarlAnzeige,0),0) | H40: =IF($D40="",0,YEAR($D40))
B41: 10 | G41: =IFERROR(MATCH($C41,DarlAnzeige,0),0) | H41: =IF($D41="",0,YEAR($D41))
B42: 11 | G42: =IFERROR(MATCH($C42,DarlAnzeige,0),0) | H42: =IF($D42="",0,YEAR($D42))
B43: 12 | G43: =IFERROR(MATCH($C43,DarlAnzeige,0),0) | H43: =IF($D43="",0,YEAR($D43))
... B71: 40 | G71: =IFERROR(MATCH($C71,DarlAnzeige,0),0) | H71: =IF($D71="",0,YEAR($D71))
B74: ="C · Kennzahlen je Darlehen zum "&TEXT(DAY(Stichtag),"00")&"."&TEXT(MONTH(Stichtag),"00")&"."&YEAR(Stichtag)
B75: Nr | C75: Bank | D75: Betrag | E75: Rate/Monat | F75: Restschuld | G75: Rest bei Bindungsende | H75: Volltilgung | I75: Zinsen gesamt | J75: Ersatz-Guthaben | K75: Deckung | L75: Sonder­tilgung Jahr | M75: davon zulässig
B76: 1 | C76: =IF(INDEX(DarlBelegt,1)=0,"–",IF(INDEX(DarlBank,1)="","Darlehen",INDEX(DarlBank,1))) | D76: =IF(INDEX(DarlBelegt,1)=0,"",INDEX(DarlBetrag,1)) | E76: =IF(INDEX(DarlBelegt,1)=0,"",SUMIFS(TilgZins,TilgDarl,1,TilgDatum,EOMONTH(Stichtag,0)+1)+SUMIFS(TilgTilgung,TilgDarl,1,TilgDatum,EOMONTH(Stichtag,0)+1)+SUMIFS(TilgErsatz,TilgDarl,1,TilgDatum,EOMONTH(Stichtag,0)+1)) | F76: =IF(INDEX(DarlBelegt,1)=0,"",MAX(0,INDEX(DarlBetrag,1)-SUMIFS(TilgTilgung,TilgDarl,1,TilgDatum,"<="&Stichtag)-SUMIFS(TilgSonder,TilgDarl,1,TilgDatum,"<="&Stichtag))) | G76: =IF(INDEX(DarlBelegt,1)=0,"",IF(INDEX(DarlBindung,1)="","",MAX(0,INDEX(DarlBetrag,1)-SUMIFS(TilgTilgung,TilgDarl,1,TilgDatum,"<="&INDEX(DarlBindung,1))-SUMIFS(TilgSonder,TilgDarl,1,TilgDatum,"<="&INDEX(DarlBindung,1))))) | H76: =IF(INDEX(DarlBelegt,1)=0,"",IF(SUMIFS(TilgAktiv,TilgDarl,1)>=480,"über 30 Jahre",TEXT(MONTH(EOMONTH(INDEX(DarlAuszahlung,1),SUMIFS(TilgAktiv,TilgDarl,1)-1)+1),"00")&"."&YEAR(EOMONTH(INDEX(DarlAuszahlung,1),SUMIFS(TilgAktiv,TilgDarl,1)-1)+1))) | I76: =IF(INDEX(DarlBelegt,1)=0,"",SUMIFS(TilgZins,TilgDarl,1)) | J76: =IF(INDEX(DarlBelegt,1)=0,"",IF(INDEX(DarlErsatzRate,1)=0,"",SUMIFS(TilgErsatz,TilgDarl,1,TilgDatum,"<="&Stichtag)+SUMIFS(TilgErtrag,TilgDarl,1,TilgDatum,"<="&Stichtag))) | K76: =IF(INDEX(DarlBelegt,1)=0,"",IF(OR(INDEX(DarlErsatzRate,1)=0,MAX(0,INDEX(DarlBetrag,1)-SUMIFS(TilgTilgung,TilgDarl,1,TilgDatum,"<="&Stichtag)-SUMIFS(TilgSonder,TilgDarl,1,TilgDatum,"<="&Stichtag))=0),"",(SUMIFS(TilgErsatz,TilgDarl,1,TilgDatum,"<="&Stichtag)+SUMIFS(TilgErtrag,TilgDarl,1,TilgDatum,"<="&Stichtag))/MAX(0,INDEX(DarlBetrag,1)-SUMIFS(TilgTilgung,TilgDarl,1,TilgDatum,"<="&Stichtag)-SUMIFS(TilgSonder,TilgDarl,1,TilgDatum,"<="&Stichtag))*100)) | L76: =IF(INDEX(DarlBelegt,1)=0,"",SUMIFS(SondBetrag,SondDarl,1,SondJahr,Jahr)) | M76: =IF(INDEX(DarlBelegt,1)=0,"",INDEX(DarlBetrag,1)*INDEX(DarlSonderrecht,1)/100)
B77: 2 | C77: =IF(INDEX(DarlBelegt,2)=0,"–",IF(INDEX(DarlBank,2)="","Darlehen",INDEX(DarlBank,2))) | D77: =IF(INDEX(DarlBelegt,2)=0,"",INDEX(DarlBetrag,2)) | E77: =IF(INDEX(DarlBelegt,2)=0,"",SUMIFS(TilgZins,TilgDarl,2,TilgDatum,EOMONTH(Stichtag,0)+1)+SUMIFS(TilgTilgung,TilgDarl,2,TilgDatum,EOMONTH(Stichtag,0)+1)+SUMIFS(TilgErsatz,TilgDarl,2,TilgDatum,EOMONTH(Stichtag,0)+1)) | F77: =IF(INDEX(DarlBelegt,2)=0,"",MAX(0,INDEX(DarlBetrag,2)-SUMIFS(TilgTilgung,TilgDarl,2,TilgDatum,"<="&Stichtag)-SUMIFS(TilgSonder,TilgDarl,2,TilgDatum,"<="&Stichtag))) | G77: =IF(INDEX(DarlBelegt,2)=0,"",IF(INDEX(DarlBindung,2)="","",MAX(0,INDEX(DarlBetrag,2)-SUMIFS(TilgTilgung,TilgDarl,2,TilgDatum,"<="&INDEX(DarlBindung,2))-SUMIFS(TilgSonder,TilgDarl,2,TilgDatum,"<="&INDEX(DarlBindung,2))))) | H77: =IF(INDEX(DarlBelegt,2)=0,"",IF(SUMIFS(TilgAktiv,TilgDarl,2)>=480,"über 30 Jahre",TEXT(MONTH(EOMONTH(INDEX(DarlAuszahlung,2),SUMIFS(TilgAktiv,TilgDarl,2)-1)+1),"00")&"."&YEAR(EOMONTH(INDEX(DarlAuszahlung,2),SUMIFS(TilgAktiv,TilgDarl,2)-1)+1))) | I77: =IF(INDEX(DarlBelegt,2)=0,"",SUMIFS(TilgZins,TilgDarl,2)) | J77: =IF(INDEX(DarlBelegt,2)=0,"",IF(INDEX(DarlErsatzRate,2)=0,"",SUMIFS(TilgErsatz,TilgDarl,2,TilgDatum,"<="&Stichtag)+SUMIFS(TilgErtrag,TilgDarl,2,TilgDatum,"<="&Stichtag))) | K77: =IF(INDEX(DarlBelegt,2)=0,"",IF(OR(INDEX(DarlErsatzRate,2)=0,MAX(0,INDEX(DarlBetrag,2)-SUMIFS(TilgTilgung,TilgDarl,2,TilgDatum,"<="&Stichtag)-SUMIFS(TilgSonder,TilgDarl,2,TilgDatum,"<="&Stichtag))=0),"",(SUMIFS(TilgErsatz,TilgDarl,2,TilgDatum,"<="&Stichtag)+SUMIFS(TilgErtrag,TilgDarl,2,TilgDatum,"<="&Stichtag))/MAX(0,INDEX(DarlBetrag,2)-SUMIFS(TilgTilgung,TilgDarl,2,TilgDatum,"<="&Stichtag)-SUMIFS(TilgSonder,TilgDarl,2,TilgDatum,"<="&Stichtag))*100)) | L77: =IF(INDEX(DarlBelegt,2)=0,"",SUMIFS(SondBetrag,SondDarl,2,SondJahr,Jahr)) | M77: =IF(INDEX(DarlBelegt,2)=0,"",INDEX(DarlBetrag,2)*INDEX(DarlSonderrecht,2)/100)
B78: 3 | C78: =IF(INDEX(DarlBelegt,3)=0,"–",IF(INDEX(DarlBank,3)="","Darlehen",INDEX(DarlBank,3))) | D78: =IF(INDEX(DarlBelegt,3)=0,"",INDEX(DarlBetrag,3)) | E78: =IF(INDEX(DarlBelegt,3)=0,"",SUMIFS(TilgZins,TilgDarl,3,TilgDatum,EOMONTH(Stichtag,0)+1)+SUMIFS(TilgTilgung,TilgDarl,3,TilgDatum,EOMONTH(Stichtag,0)+1)+SUMIFS(TilgErsatz,TilgDarl,3,TilgDatum,EOMONTH(Stichtag,0)+1)) | F78: =IF(INDEX(DarlBelegt,3)=0,"",MAX(0,INDEX(DarlBetrag,3)-SUMIFS(TilgTilgung,TilgDarl,3,TilgDatum,"<="&Stichtag)-SUMIFS(TilgSonder,TilgDarl,3,TilgDatum,"<="&Stichtag))) | G78: =IF(INDEX(DarlBelegt,3)=0,"",IF(INDEX(DarlBindung,3)="","",MAX(0,INDEX(DarlBetrag,3)-SUMIFS(TilgTilgung,TilgDarl,3,TilgDatum,"<="&INDEX(DarlBindung,3))-SUMIFS(TilgSonder,TilgDarl,3,TilgDatum,"<="&INDEX(DarlBindung,3))))) | H78: =IF(INDEX(DarlBelegt,3)=0,"",IF(SUMIFS(TilgAktiv,TilgDarl,3)>=480,"über 30 Jahre",TEXT(MONTH(EOMONTH(INDEX(DarlAuszahlung,3),SUMIFS(TilgAktiv,TilgDarl,3)-1)+1),"00")&"."&YEAR(EOMONTH(INDEX(DarlAuszahlung,3),SUMIFS(TilgAktiv,TilgDarl,3)-1)+1))) | I78: =IF(INDEX(DarlBelegt,3)=0,"",SUMIFS(TilgZins,TilgDarl,3)) | J78: =IF(INDEX(DarlBelegt,3)=0,"",IF(INDEX(DarlErsatzRate,3)=0,"",SUMIFS(TilgErsatz,TilgDarl,3,TilgDatum,"<="&Stichtag)+SUMIFS(TilgErtrag,TilgDarl,3,TilgDatum,"<="&Stichtag))) | K78: =IF(INDEX(DarlBelegt,3)=0,"",IF(OR(INDEX(DarlErsatzRate,3)=0,MAX(0,INDEX(DarlBetrag,3)-SUMIFS(TilgTilgung,TilgDarl,3,TilgDatum,"<="&Stichtag)-SUMIFS(TilgSonder,TilgDarl,3,TilgDatum,"<="&Stichtag))=0),"",(SUMIFS(TilgErsatz,TilgDarl,3,TilgDatum,"<="&Stichtag)+SUMIFS(TilgErtrag,TilgDarl,3,TilgDatum,"<="&Stichtag))/MAX(0,INDEX(DarlBetrag,3)-SUMIFS(TilgTilgung,TilgDarl,3,TilgDatum,"<="&Stichtag)-SUMIFS(TilgSonder,TilgDarl,3,TilgDatum,"<="&Stichtag))*100)) | L78: =IF(INDEX(DarlBelegt,3)=0,"",SUMIFS(SondBetrag,SondDarl,3,SondJahr,Jahr)) | M78: =IF(INDEX(DarlBelegt,3)=0,"",INDEX(DarlBetrag,3)*INDEX(DarlSonderrecht,3)/100)
